Workbook

Sheet Inputs
A1: Securitization waterfall: inputs (synthetic data, not a real transaction)
A3: Selected scenario number | B3: 1 | C3: 1 to 6 standard; 7 to 10 custom slots
A4: Selected cpr | B4: =INDEX(Inputs!$B$45:$B$54,Inputs!$B$3) -> 0.1
A5: Selected cdr | B5: =INDEX(Inputs!$C$45:$C$54,Inputs!$B$3) -> 0.03
A6: Selected sev | B6: =INDEX(Inputs!$D$45:$D$54,Inputs!$B$3) -> 0.4
A7: Selected lag | B7: =INDEX(Inputs!$E$45:$E$54,Inputs!$B$3) -> 6
A8: Selected shift | B8: =INDEX(Inputs!$F$45:$F$54,Inputs!$B$3) -> 0
A9: Monthly default rate | B9: =1-(1-Inputs!$B$5)^(1/12) -> 0.0025350486
A10: Single monthly mortality | B10: =1-(1-Inputs!$B$4)^(1/12) -> 0.008741611
A11: Index start | B11: 0.043
A12: Index long run | B12: 0.0325
A13: Index decay (months) | B13: 24
A14: Senior fees, annual (servicing + trustee) | B14: 0.0063
A15: Initial and target reserve | B15: 3000000
A16: Pro rata start (1) or sequential (0) | B16: 0
A17: Swap hedge on floating notes (1/0) | B17: 0
A18: Swap fixed rate | B18: 0.036
A19: Retirement tolerance (USD) | B19: 1e-06
A20: Shortfall tolerance (USD) | B20: 1
A21: Class A original balance | B21: 300000000
A22: Class A floating (1) or fixed (0) | B22: 1
... A35: Class C IC trigger | B35: 1.15
A36: Pool balance | B36: =SUM(Inputs!$B$58:$B$67) -> 400000000
A37: Residual par (pool + reserve - notes) | B37: =Inputs!$B$36+Inputs!$B$15-Inputs!$B$21-Inputs!$B$26-Inputs!$B$31 -> 33000000
A44: Scenario | B44: CPR | C44: CDR | D44: Severity | E44: Lag (months) | F44: Index shift
A45: Base | B45: 0.1 | C45: 0.03 | D45: 0.4 | E45: 6 | F45: 0
A46: Mild stress | B46: 0.1 | C46: 0.06 | D46: 0.5 | E46: 6 | F46: 0
A47: Stress | B47: 0.06 | C47: 0.12 | D47: 0.6 | E47: 9 | F47: 0
A48: Severe stress | B48: 0.04 | C48: 0.2 | D48: 0.7 | E48: 12 | F48: 0
A49: Fast prepay | B49: 0.3 | C49: 0.03 | D49: 0.4 | E49: 6 | F49: 0
A50: Rate shock | B50: 0.1 | C50: 0.06 | D50: 0.5 | E50: 6 | F50: 0.03
A51: Custom 1 | B51: 0.1 | C51: 0.03 | D51: 0.4 | E51: 6 | F51: 0
A52: Custom 2 | B52: 0.1 | C52: 0.03 | D52: 0.4 | E52: 6 | F52: 0
A53: Custom 3 | B53: 0.1 | C53: 0.03 | D53: 0.4 | E53: 6 | F53: 0
A54: Custom 4 | B54: 0.1 | C54: 0.03 | D54: 0.4 | E54: 6 | F54: 0
A57: Pool rep line | B57: Balance | C57: WAC | D57: Term (months)
A58: L01 | B58: 39000000 | C58: 0.073 | D58: 36
A59: L02 | B59: 75500000 | C59: 0.078 | D59: 48
A60: L03 | B60: 21600000 | C60: 0.083 | D60: 48
A61: L04 | B61: 67200000 | C61: 0.088 | D61: 60
...

Sheet Pool
A4: Period | B4: L1_rem | C4: L1_beg | D4: L1_def | E4: L1_int | F4: L1_sch | G4: L1_pre | H4: L1_end | I4: L2_rem | J4: L2_beg | K4: L2_def | L4: L2_int | M4: L2_sch | N4: L2_pre | O4: L2_end | P4: L3_rem | Q4: L3_beg | R4: L3_def | S4: L3_int | T4: L3_sch | U4: L3_pre | V4: L3_end | W4: L4_rem | X4: L4_beg | Y4: L4_def | Z4: L4_int | AA4: L4_sch | AB4: L4_pre | AC4: L4_end | AD4: L5_rem | AE4: L5_beg | AF4: L5_def | AG4: L5_int | AH4: L5_sch | AI4: L5_pre | AJ4: L5_end | AK4: L6_rem | AL4: L6_beg | AM4: L6_def | AN4: L6_int | AO4: L6_sch | AP4: L6_pre | AQ4: L6_end | AR4: L7_rem | AS4: L7_beg | AT4: L7_def | AU4: L7_int | AV4: L7_sch | AW4: L7_pre | AX4: L7_end | AY4: L8_rem | AZ4: L8_beg | BA4: L8_def | BB4: L8_int | BC4: L8_sch | BD4: L8_pre | BE4: L8_end | BF4: L9_rem | BG4: L9_beg | BH4: L9_def | BI4: L9_int | BJ4: L9_sch | BK4: L9_pre | BL4: L9_end | BM4: L10_rem | BN4: L10_beg | BO4: L10_def | BP4: L10_int | BQ4: L10_sch | BR4: L10_pre | BS4: L10_end | BT4: tot_beg | BU4: tot_defaults | BV4: tot_interest | BW4: tot_sched | BX4: tot_prepay | BY4: tot_end | BZ4: recov | CA4: pending | CB4: value | CC4: cash | CD4: cum_loss
H5: 0 | O5: 0 | V5: 0 | AC5: 0 | AJ5: 0 | AQ5: 0 | AX5: 0 | BE5: 0 | BL5: 0 | BS5: 0 | BY5: 0 | CA5: 0 | CD5: 0
A6: =ROW()-5 -> 1 | B6: =Inputs!$D$58-(A6-1) -> 36 | C6: =IF(B6<=0,0,IF(A6=1,Inputs!$B$58,H5)) -> 39000000 | D6: =C6*Inputs!$B$9 -> 98866.896 | E6: =(C6-D6)*Inputs!$C$58/12 -> 236648.56 | F6: =IF(B6<=0,0,IF(B6=1,C6-D6,MIN((C6-D6)*(Inputs!$C$58/12)/(1-(1+Inputs!$C$58/12)^(-B6))-E6,C6-D6))) -> 969848.55 | G6: =(C6-D6-F6)*Inputs!$B$10 -> 331580.53 | H6: =C6-D6-F6-G6 -> 37599704 | I6: =Inputs!$D$59-(A6-1) -> 48 | J6: =IF(I6<=0,0,IF(A6=1,Inputs!$B$59,O5)) -> 75500000 | K6: =J6*Inputs!$B$9 -> 191396.17 | L6: =(J6-K6)*Inputs!$C$59/12 -> 489505.92 | M6: =IF(I6<=0,0,IF(I6=1,J6-K6,MIN((J6-K6)*(Inputs!$C$59/12)/(1-(1+Inputs!$C$59/12)^(-I6))-L6,J6-K6))) -> 1341935.4 | N6: =(J6-K6-M6)*Inputs!$B$10 -> 646587.84 | O6: =J6-K6-M6-N6 -> 73320081 | P6: =Inputs!$D$60-(A6-1) -> 48 | Q6: =IF(P6<=0,0,IF(A6=1,Inputs!$B$60,V5)) -> 21600000 | R6: =Q6*Inputs!$B$9 -> 54757.05 | S6: =(Q6-R6)*Inputs!$C$60/12 -> 149021.26 | T6: =IF(P6<=0,0,IF(P6=1,Q6-R6,MIN((Q6-R6)*(Inputs!$C$60/12)/(1-(1+Inputs!$C$60/12)^(-P6))-S6,Q6-R6))) -> 380000.37 | U6: =(Q6-R6-T6)*Inputs!$B$10 -> 185018.32 | V6: =Q6-R6-T6-U6 -> 20980224 | W6: =Inputs!$D$61-(A6-1) -> 60 | X6: =IF(W6<=0,0,IF(A6=1,Inputs!$B$61,AC5)) -> 67200000 | Y6: =X6*Inputs!$B$9 -> 170355.27 | Z6: =(X6-Y6)*Inputs!$C$61/12 -> 491550.73 | AA6: =IF(W6<=0,0,IF(W6=1,X6-Y6,MIN((X6-Y6)*(Inputs!$C$61/12)/(1-(1+Inputs!$C$61/12)^(-W6))-Z6,X6-Y6))) -> 893377.15 | AB6: =(X6-Y6-AA6)*Inputs!$B$10 -> 578137.52 | AC6: =X6-Y6-AA6-AB6 -> 65558130 | AD6: =Inputs!$D$62-(A6-1) -> 60 | AE6: =IF(AD6<=0,0,IF(A6=1,Inputs!$B$62,AJ5)) -> 19000000 | AF6: =AE6*Inputs!$B$9 -> 48165.924 | AG6: =(AE6-AF6)*Inputs!$C$62/12 -> 146876.71 | AH6: =IF(AD6<=0,0,IF(AD6=1,AE6-AF6,MIN((AE6-AF6)*(Inputs!$C$62/12)/(1-(1+Inputs!$C$62/12)^(-AD6))-AG6,AE6-AF6))) -> 249297.3 | AI6: =(AE6-AF6-AH6)*Inputs!$B$10 -> 163490.3 | AJ6: =AE6-AF6-AH6-AI6 -> 18539046 | AK6: =Inputs!$D$63-(A6-1) -> 60 | AL6: =IF(AK6<=0,0,IF(A6=1,Inputs!$B$63,AQ5)) -> 22700000 | AM6: =AL6*Inputs!$B$9 -> 57545.604 | AN6: =(AL6-AM6)*Inputs!$C$63/12 -> 180196.2 | AO6: =IF(AK6<=0,0,IF(AK6=1,AL6-AM6,MIN((AL6-AM6)*(Inputs!$C$63/12)/(1-(1+Inputs!$C$63/12)^(-AK6))-AN6,AL6-AM6))) -> 295890.94 | AP6: =(AL6-AM6-AO6)*Inputs!$B$10 -> 195344.96 | AQ6: =AL6-AM6-AO6-AP6 -> 22151218 | AR6: =Inputs!$D$64-(A6-1) -> 72 | AS6: =IF(AR6<=0,0,IF(A6=1,Inputs!$B$64,AX5)) -> 35200000 | AT6: =AS6*Inputs!$B$9 -> 89233.711 | AU6: =(AS6-AT6)*Inputs!$C$64/12 -> 286737.92 | AV6: =IF(AR6<=0,0,IF(AR6=1,AS6-AT6,MIN((AS6-AT6)*(Inputs!$C$64/12)/(1-(1+Inputs!$C$64/12)^(-AR6))-AU6,AS6-AT6))) -> 360182.87 | AW6: =(AS6-AT6-AV6)*Inputs!$B$10 -> 303776.08 | AX6: =AS6-AT6-AV6-AW6 -> 34446807 | AY6: =Inputs!$D$65-(A6-1) -> 72 | AZ6: =IF(AY6<=0,0,IF(A6=1,Inputs!$B$65,BE5)) -> 36400000 | BA6: =AZ6*Inputs!$B$9 -> 92275.77 | BB6: =(AZ6-BA6)*Inputs!$C$65/12 -> 311641.3 | BC6: =IF(AY6<=0,0,IF(AY6=1,AZ6-BA6,MIN((AZ6-BA6)*(Inputs!$C$65/12)/(1-(1+Inputs!$C$65/12)^(-AY6))-BB6,AZ6-BA6))) -> 366495.47 | BD6: =(AZ6-BA6-BC6)*Inputs!$B$10 -> 314184.24 | BE6: =AZ6-BA6-BC6-BD6 -> 35627045 | BF6: =Inputs!$D$66-(A6-1) -> 84 | BG6: =IF(BF6<=0,0,IF(A6=1,Inputs!$B$66,BL5)) -> 36100000 | BH6: =BG6*Inputs!$B$9 -> 91515.255 | BI6: =(BG6-BH6)*Inputs!$C$66/12 -> 316574.6 | BJ6: =IF(BF6<=0,0,IF(BF6=1,BG6-BH6,MIN((BG6-BH6)*(Inputs!$C$66/12)/(1-(1+Inputs!$C$66/12)^(-BF6))-BI6,BG6-BH6))) -> 291491.59 | BK6: =(BG6-BH6-BJ6)*Inputs!$B$10 -> 312224.06 | BL6: =BG6-BH6-BJ6-BK6 -> 35404769 | BM6: =Inputs!$D$67-(A6-1) -> 84 | BN6: =IF(BM6<=0,0,IF(A6=1,Inputs!$B$67,BS5)) -> 47300000 | BO6: =BN6*Inputs!$B$9 -> 119907.8 | BP6: =(BN6-BO6)*Inputs!$C$67/12 -> 434450.02 | BQ6: =IF(BM6<=0,0,IF(BM6=1,BN6-BO6,MIN((BN6-BO6)*(Inputs!$C$67/12)/(1-(1+Inputs!$C$67/12)^(-BM6))-BP6,BN6-BO6))) -> 374628.99 | BR6: =(BN6-BO6-BQ6)*Inputs!$B$10 -> 409155.15 | BS6: =BN6-BO6-BQ6-BR6 -> 46396308 | BT6: =C6+J6+Q6+X6+AE6+AL6+AS6+AZ6+BG6+BN6 -> 400000000 | BU6: =D6+K6+R6+Y6+AF6+AM6+AT6+BA6+BH6+BO6 -> 1014019.4 | BV6: =E6+L6+S6+Z6+AG6+AN6+AU6+BB6+BI6+BP6 -> 3043203.2 | BW6: =F6+M6+T6+AA6+AH6+AO6+AV6+BC6+BJ6+BQ6 -> 5523148.6 | BX6: =G6+N6+U6+AB6+AI6+AP6+AW6+BD6+BK6+BR6 -> 3439499 | BY6: =H6+O6+V6+AC6+AJ6+AQ6+AX6+BE6+BL6+BS6 -> 3.9002333e+08 | BZ6: =IF(A6>Inputs!$B$7,(1-Inputs!$B$6)*INDEX($BU$6:$BU$125,A6-Inputs!$B$7),0) -> 0 | CA6: =CA5+(1-Inputs!$B$6)*BU6-BZ6 -> 608411.67 | CB6: =BY6+CA6 -> 3.9063174e+08 | CC6: =BV6+BW6+BX6+BZ6 -> 12005851 | CD6: =CD5+BU6-BZ6 -> 1014019.4
A7: =ROW()-5 -> 2 | B7: =Inputs!$D$58-(A7-1) -> 35 | C7: =IF(B7<=0,0,IF(A7=1,Inputs!$B$58,H6)) -> 37599704 | D7: =C7*Inputs!$B$9 -> 95317.078 | E7: =(C7-D7)*Inputs!$C$58/12 -> 228151.69 | F7: =IF(B7<=0,0,IF(B7=1,C7-D7,MIN((C7-D7)*(Inputs!$C$58/12)/(1-(1+Inputs!$C$58/12)^(-B7))-E7,C7-D7))) -> 964766.9 | G7: =(C7-D7-F7)*Inputs!$B$10 -> 319415.14 | H7: =C7-D7-F7-G7 -> 36220205 | I7: =Inputs!$D$59-(A7-1) -> 47 | J7: =IF(I7<=0,0,IF(A7=1,Inputs!$B$59,O6)) -> 73320081 | K7: =J7*Inputs!$B$9 -> 185869.97 | L7: =(J7-K7)*Inputs!$C$59/12 -> 475372.37 | M7: =IF(I7<=0,0,IF(I7=1,J7-K7,MIN((J7-K7)*(Inputs!$C$59/12)/(1-(1+Inputs!$C$59/12)^(-I7))-L7,J7-K7))) -> 1335457 | N7: =(J7-K7-M7)*Inputs!$B$10 -> 627636.77 | O7: =J7-K7-M7-N7 -> 71171117 | P7: =Inputs!$D$60-(A7-1) -> 47 | Q7: =IF(P7<=0,0,IF(A7=1,Inputs!$B$60,V6)) -> 20980224 | R7: =Q7*Inputs!$B$9 -> 53185.888 | S7: =(Q7-R7)*Inputs!$C$60/12 -> 144745.35 | T7: =IF(P7<=0,0,IF(P7=1,Q7-R7,MIN((Q7-R7)*(Inputs!$C$60/12)/(1-(1+Inputs!$C$60/12)^(-P7))-S7,Q7-R7))) -> 378322.41 | U7: =(Q7-R7-T7)*Inputs!$B$10 -> 179628.88 | V7: =Q7-R7-T7-U7 -> 20369087 | W7: =Inputs!$D$61-(A7-1) -> 59 | X7: =IF(W7<=0,0,IF(A7=1,Inputs!$B$61,AC6)) -> 65558130 | Y7: =X7*Inputs!$B$9 -> 166193.05 | Z7: =(X7-Y7)*Inputs!$C$61/12 -> 479540.87 | AA7: =IF(W7<=0,0,IF(W7=1,X7-Y7,MIN((X7-Y7)*(Inputs!$C$61/12)/(1-(1+Inputs!$C$61/12)^(-W7))-Z7,X7-Y7))) -> 889800.34 | AB7: =(X7-Y7-AA7)*Inputs!$B$10 -> 563852.58 | AC7: =X7-Y7-AA7-AB7 -> 63938284 | AD7: =Inputs!$D$62-(A7-1) -> 59 | AE7: =IF(AD7<=0,0,IF(A7=1,Inputs!$B$62,AJ6)) -> 18539046 | AF7: =AE7*Inputs!$B$9 -> 46997.384 | AG7: =(AE7-AF7)*Inputs!$C$62/12 -> 143313.38 | AH7: =IF(AD7<=0,0,IF(AD7=1,AE7-AF7,MIN((AE7-AF7)*(Inputs!$C$62/12)/(1-(1+Inputs!$C$62/12)^(-AD7))-AG7,AE7-AF7))) -> 248401.9 | AI7: =(AE7-AF7-AH7)*Inputs!$B$10 -> 159478.87 | AJ7: =AE7-AF7-AH7-AI7 -> 18084168 | AK7: =Inputs!$D$63-(A7-1) -> 59 | AL7: =IF(AK7<=0,0,IF(A7=1,Inputs!$B$63,AQ6)) -> 22151218 | AM7: =AL7*Inputs!$B$9 -> 56154.416 | AN7: =(AL7-AM7)*Inputs!$C$63/12 -> 175839.88 | AO7: =IF(AK7<=0,0,IF(AK7=1,AL7-AM7,MIN((AL7-AM7)*(Inputs!$C$63/12)/(1-(1+Inputs!$C$63/12)^(-AK7))-AN7,AL7-AM7))) -> 294889.13 | AP7: =(AL7-AM7-AO7)*Inputs!$B$10 -> 190568.65 | AQ7: =AL7-AM7-AO7-AP7 -> 21609606 | AR7: =Inputs!$D$64-(A7-1) -> 71 | AS7: =IF(AR7<=0,0,IF(A7=1,Inputs!$B$64,AX6)) -> 34446807 | AT7: =AS7*Inputs!$B$9 -> 87324.331 | AU7: =(AS7-AT7)*Inputs!$C$64/12 -> 280602.44 | AV7: =IF(AR7<=0,0,IF(AR7=1,AS7-AT7,MIN((AS7-AT7)*(Inputs!$C$64/12)/(1-(1+Inputs!$C$64/12)^(-AR7))-AU7,AS7-AT7))) -> 359037.58 | AW7: =(AS7-AT7-AV7)*Inputs!$B$10 -> 297218.67 | AX7: =AS7-AT7-AV7-AW7 -> 33703227 | AY7: =Inputs!$D$65-(A7-1) -> 71 | AZ7: =IF(AY7<=0,0,IF(A7=1,Inputs!$B$65,BE6)) -> 35627045 | BA7: =AZ7*Inputs!$B$9 -> 90316.29 | BB7: =(AZ7-BA7)*Inputs!$C$65/12 -> 305023.58 | BC7: =IF(AY7<=0,0,IF(AY7=1,AZ7-BA7,MIN((AZ7-BA7)*(Inputs!$C$65/12)/(1-(1+Inputs!$C$65/12)^(-AY7))-BB7,AZ7-BA7))) -> 365481.1 | BD7: =(AZ7-BA7-BC7)*Inputs!$B$10 -> 307453.36 | BE7: =AZ7-BA7-BC7-BD7 -> 34863794 | BF7: =Inputs!$D$66-(A7-1) -> 83 | BG7: =IF(BF7<=0,0,IF(A7=1,Inputs!$B$66,BL6)) -> 35404769 | BH7: =BG7*Inputs!$B$9 -> 89752.811 | BI7: =(BG7-BH7)*Inputs!$C$66/12 -> 310477.85 | BJ7: =IF(BF7<=0,0,IF(BF7=1,BG7-BH7,MIN((BG7-BH7)*(Inputs!$C$66/12)/(1-(1+Inputs!$C$66/12)^(-BF7))-BI7,BG7-BH7))) -> 290744.85 | BK7: =(BG7-BH7-BJ7)*Inputs!$B$10 -> 306168.55 | BL7: =BG7-BH7-BJ7-BK7 -> 34718103 | BM7: =Inputs!$D$67-(A7-1) -> 83 | BN7: =IF(BM7<=0,0,IF(A7=1,Inputs!$B$67,BS6)) -> 46396308 | BO7: =BN7*Inputs!$B$9 -> 117616.9 | BP7: =(BN7-BO7)*Inputs!$C$67/12 -> 426149.61 | BQ7: =IF(BM7<=0,0,IF(BM7=1,BN7-BO7,MIN((BN7-BO7)*(Inputs!$C$67/12)/(1-(1+Inputs!$C$67/12)^(-BM7))-BP7,BN7-BO7))) -> 373823.62 | BR7: =(BN7-BO7-BQ7)*Inputs!$B$10 -> 401282.49 | BS7: =BN7-BO7-BQ7-BR7 -> 45503585 | BT7: =C7+J7+Q7+X7+AE7+AL7+AS7+AZ7+BG7+BN7 -> 3.9002333e+08 | BU7: =D7+K7+R7+Y7+AF7+AM7+AT7+BA7+BH7+BO7 -> 988728.11 | BV7: =E7+L7+S7+Z7+AG7+AN7+AU7+BB7+BI7+BP7 -> 2969217 | BW7: =F7+M7+T7+AA7+AH7+AO7+AV7+BC7+BJ7+BQ7 -> 5500724.8 | BX7: =G7+N7+U7+AB7+AI7+AP7+AW7+BD7+BK7+BR7 -> 3352704 | BY7: =H7+O7+V7+AC7+AJ7+AQ7+AX7+BE7+BL7+BS7 -> 3.8018118e+08 | BZ7: =IF(A7>Inputs!$B$7,(1-Inputs!$B$6)*INDEX($BU$6:$BU$125,A7-Inputs!$B$7),0) -> 0 | CA7: =CA6+(1-Inputs!$B$6)*BU7-BZ7 -> 1201648.5 | CB7: =BY7+CA7 -> 3.8138282e+08 | CC7: =BV7+BW7+BX7+BZ7 -> 11822646 | CD7: =CD6+BU7-BZ7 -> 2002747.6
A8: =ROW()-5 -> 3 | B8: =Inputs!$D$58-(A8-1) -> 34 | C8: =IF(B8<=0,0,IF(A8=1,Inputs!$B$58,H7)) -> 36220205 | D8: =C8*Inputs!$B$9 -> 91819.98 | E8: =(C8-D8)*Inputs!$C$58/12 -> 219781.01 | F8: =IF(B8<=0,0,IF(B8=1,C8-D8,MIN((C8-D8)*(Inputs!$C$58/12)/(1-(1+Inputs!$C$58/12)^(-B8))-E8,C8-D8))) -> 959711.88 | G8: =(C8-D8-F8)*Inputs!$B$10 -> 307430.86 | H8: =C8-D8-F8-G8 -> 34861242 | I8: =Inputs!$D$59-(A8-1) -> 46 | J8: =IF(I8<=0,0,IF(A8=1,Inputs!$B$59,O7)) -> 71171117 | K8: =J8*Inputs!$B$9 -> 180422.24 | L8: =(J8-K8)*Inputs!$C$59/12 -> 461439.52 | M8: =IF(I8<=0,0,IF(I8=1,J8-K8,MIN((J8-K8)*(Inputs!$C$59/12)/(1-(1+Inputs!$C$59/12)^(-I8))-L8,J8-K8))) -> 1329009.8 | N8: =(J8-K8-M8)*Inputs!$B$10 -> 608955.35 | O8: =J8-K8-M8-N8 -> 69052729 | P8: =Inputs!$D$60-(A8-1) -> 46 | Q8: =IF(P8<=0,0,IF(A8=1,Inputs!$B$60,V7)) -> 20369087 | R8: =Q8*Inputs!$B$9 -> 51636.626 | S8: =(Q8-R8)*Inputs!$C$60/12 -> 140529.03 | T8: =IF(P8<=0,0,IF(P8=1,Q8-R8,MIN((Q8-R8)*(Inputs!$C$60/12)/(1-(1+Inputs!$C$60/12)^(-P8))-S8,Q8-R8))) -> 376651.86 | U8: =(Q8-R8-T8)*Inputs!$B$10 -> 174314.7 | V8: =Q8-R8-T8-U8 -> 19766484 | W8: =Inputs!$D$61-(A8-1) -> 58 | X8: =IF(W8<=0,0,IF(A8=1,Inputs!$B$61,AC7)) -> 63938284 | Y8: =X8*Inputs!$B$9 -> 162086.66 | Z8: =(X8-Y8)*Inputs!$C$61/12 -> 467692.11 | AA8: =IF(W8<=0,0,IF(W8=1,X8-Y8,MIN((X8-Y8)*(Inputs!$C$61/12)/(1-(1+Inputs!$C$61/12)^(-W8))-Z8,X8-Y8))) -> 886237.85 | AB8: =(X8-Y8-AA8)*Inputs!$B$10 -> 549759.56 | AC8: =X8-Y8-AA8-AB8 -> 62340200 | AD8: =Inputs!$D$62-(A8-1) -> 58 | AE8: =IF(AD8<=0,0,IF(A8=1,Inputs!$B$62,AJ7)) -> 18084168 | AF8: =AE8*Inputs!$B$9 -> 45844.246 | AG8: =(AE8-AF8)*Inputs!$C$62/12 -> 139797.01 | AH8: =IF(AD8<=0,0,IF(AD8=1,AE8-AF8,MIN((AE8-AF8)*(Inputs!$C$62/12)/(1-(1+Inputs!$C$62/12)^(-AD8))-AG8,AE8-AF8))) -> 247509.71 | AI8: =(AE8-AF8-AH8)*Inputs!$B$10 -> 155520.38 | AJ8: =AE8-AF8-AH8-AI8 -> 17635294 | AK8: =Inputs!$D$63-(A8-1) -> 58 | AL8: =IF(AK8<=0,0,IF(A8=1,Inputs!$B$63,AQ7)) -> 21609606 | AM8: =AL8*Inputs!$B$9 -> 54781.403 | AN8: =(AL8-AM8)*Inputs!$C$63/12 -> 171540.48 | AO8: =IF(AK8<=0,0,IF(AK8=1,AL8-AM8,MIN((AL8-AM8)*(Inputs!$C$63/12)/(1-(1+Inputs!$C$63/12)^(-AK8))-AN8,AL8-AM8))) -> 293890.71 | AP8: =(AL8-AM8-AO8)*Inputs!$B$10 -> 185854.82 | AQ8: =AL8-AM8-AO8-AP8 -> 21075079 | AR8: =Inputs!$D$64-(A8-1) -> 70 | AS8: =IF(AR8<=0,0,IF(A8=1,Inputs!$B$64,AX7)) -> 33703227 | AT8: =AS8*Inputs!$B$9 -> 85439.318 | AU8: =(AS8-AT8)*Inputs!$C$64/12 -> 274545.26 | AV8: =IF(AR8<=0,0,IF(AR8=1,AS8-AT8,MIN((AS8-AT8)*(Inputs!$C$64/12)/(1-(1+Inputs!$C$64/12)^(-AR8))-AU8,AS8-AT8))) -> 357895.93 | AW8: =(AS8-AT8-AV8)*Inputs!$B$10 -> 290745.03 | AX8: =AS8-AT8-AV8-AW8 -> 32969146 | AY8: =Inputs!$D$65-(A8-1) -> 70 | AZ8: =IF(AY8<=0,0,IF(A8=1,Inputs!$B$65,BE7)) -> 34863794 | BA8: =AZ8*Inputs!$B$9 -> 88381.412 | BB8: =(AZ8-BA8)*Inputs!$C$65/12 -> 298488.96 | BC8: =IF(AY8<=0,0,IF(AY8=1,AZ8-BA8,MIN((AZ8-BA8)*(Inputs!$C$65/12)/(1-(1+Inputs!$C$65/12)^(-AY8))-BB8,AZ8-BA8))) -> 364469.53 | BD8: =(AZ8-BA8-BC8)*Inputs!$B$10 -> 300807.07 | BE8: =AZ8-BA8-BC8-BD8 -> 34110136 | BF8: =Inputs!$D$66-(A8-1) -> 82 | BG8: =IF(BF8<=0,0,IF(A8=1,Inputs!$B$66,BL7)) -> 34718103 | BH8: =BG8*Inputs!$B$9 -> 88012.079 | BI8: =(BG8-BH8)*Inputs!$C$66/12 -> 304456.21 | BJ8: =IF(BF8<=0,0,IF(BF8=1,BG8-BH8,MIN((BG8-BH8)*(Inputs!$C$66/12)/(1-(1+Inputs!$C$66/12)^(-BF8))-BI8,BG8-BH8))) -> 290000.03 | BK8: =(BG8-BH8-BJ8)*Inputs!$B$10 -> 300187.71 | BL8: =BG8-BH8-BJ8-BK8 -> 34039903 | BM8: =Inputs!$D$67-(A8-1) -> 82 | BN8: =IF(BM8<=0,0,IF(A8=1,Inputs!$B$67,BS7)) -> 45503585 | BO8: =BN8*Inputs!$B$9 -> 115353.8 | BP8: =(BN8-BO8)*Inputs!$C$67/12 -> 417949.96 | BQ8: =IF(BM8<=0,0,IF(BM8=1,BN8-BO8,MIN((BN8-BO8)*(Inputs!$C$67/12)/(1-(1+Inputs!$C$67/12)^(-BM8))-BP8,BN8-BO8))) -> 373019.97 | BR8: =(BN8-BO8-BQ8)*Inputs!$B$10 -> 393505.46 | BS8: =BN8-BO8-BQ8-BR8 -> 44621706 | BT8: =C8+J8+Q8+X8+AE8+AL8+AS8+AZ8+BG8+BN8 -> 3.8018118e+08 | BU8: =D8+K8+R8+Y8+AF8+AM8+AT8+BA8+BH8+BO8 -> 963777.76 | BV8: =E8+L8+S8+Z8+AG8+AN8+AU8+BB8+BI8+BP8 -> 2896219.6 | BW8: =F8+M8+T8+AA8+AH8+AO8+AV8+BC8+BJ8+BQ8 -> 5478397.3 | BX8: =G8+N8+U8+AB8+AI8+AP8+AW8+BD8+BK8+BR8 -> 3267080.9 | BY8: =H8+O8+V8+AC8+AJ8+AQ8+AX8+BE8+BL8+BS8 -> 3.7047192e+08 | BZ8: =IF(A8>Inputs!$B$7,(1-Inputs!$B$6)*INDEX($BU$6:$BU$125,A8-Inputs!$B$7),0) -> 0 | CA8: =CA7+(1-Inputs!$B$6)*BU8-BZ8 -> 1779915.2 | CB8: =BY8+CA8 -> 3.7225184e+08 | CC8: =BV8+BW8+BX8+BZ8 -> 11641698 | CD8: =CD7+BU8-BZ8 -> 2966525.3
A9: =ROW()-5 -> 4 | B9: =Inputs!$D$58-(A9-1) -> 33 | C9: =IF(B9<=0,0,IF(A9=1,Inputs!$B$58,H8)) -> 34861242 | D9: =C9*Inputs!$B$9 -> 88374.944 | E9: =(C9-D9)*Inputs!$C$58/12 -> 211534.94 | F9: =IF(B9<=0,0,IF(B9=1,C9-D9,MIN((C9-D9)*(Inputs!$C$58/12)/(1-(1+Inputs!$C$58/12)^(-B9))-E9,C9-D9))) -> 954683.34 | G9: =(C9-D9-F9)*Inputs!$B$10 -> 295625.41 | H9: =C9-D9-F9-G9 -> 33522558 | I9: =Inputs!$D$59-(A9-1) -> 45 | J9: =IF(I9<=0,0,IF(A9=1,Inputs!$B$59,O8)) -> 69052729 | K9: =J9*Inputs!$B$9 -> 175052.03 | L9: =(J9-K9)*Inputs!$C$59/12 -> 447704.9 | M9: =IF(I9<=0,0,IF(I9=1,J9-K9,MIN((J9-K9)*(Inputs!$C$59/12)/(1-(1+Inputs!$C$59/12)^(-I9))-L9,J9-K9))) -> 1322593.8 | N9: =(J9-K9-M9)*Inputs!$B$10 -> 590540.26 | O9: =J9-K9-M9-N9 -> 66964543 | P9: =Inputs!$D$60-(A9-1) -> 45 | Q9: =IF(P9<=0,0,IF(A9=1,Inputs!$B$60,V8)) -> 19766484 | R9: =Q9*Inputs!$B$9 -> 50108.998 | S9: =(Q9-R9)*Inputs!$C$60/12 -> 136371.59 | T9: =IF(P9<=0,0,IF(P9=1,Q9-R9,MIN((Q9-R9)*(Inputs!$C$60/12)/(1-(1+Inputs!$C$60/12)^(-P9))-S9,Q9-R9))) -> 374988.69 | U9: =(Q9-R9-T9)*Inputs!$B$10 -> 169074.87 | V9: =Q9-R9-T9-U9 -> 19172311 | W9: =Inputs!$D$61-(A9-1) -> 57 | X9: =IF(W9<=0,0,IF(A9=1,Inputs!$B$61,AC8)) -> 62340200 | Y9: =X9*Inputs!$B$9 -> 158035.44 | Z9: =(X9-Y9)*Inputs!$C$61/12 -> 456002.54 | AA9: =IF(W9<=0,0,IF(W9=1,X9-Y9,MIN((X9-Y9)*(Inputs!$C$61/12)/(1-(1+Inputs!$C$61/12)^(-W9))-Z9,X9-Y9))) -> 882689.62 | AB9: =(X9-Y9-AA9)*Inputs!$B$10 -> 535856.16 | AC9: =X9-Y9-AA9-AB9 -> 60763619 | AD9: =Inputs!$D$62-(A9-1) -> 57 | AE9: =IF(AD9<=0,0,IF(A9=1,Inputs!$B$62,AJ8)) -> 17635294 | AF9: =AE9*Inputs!$B$9 -> 44706.328 | AG9: =(AE9-AF9)*Inputs!$C$62/12 -> 136327.05 | AH9: =IF(AD9<=0,0,IF(AD9=1,AE9-AF9,MIN((AE9-AF9)*(Inputs!$C$62/12)/(1-(1+Inputs!$C$62/12)^(-AD9))-AG9,AE9-AF9))) -> 246620.72 | AI9: =(AE9-AF9-AH9)*Inputs!$B$10 -> 151614.21 | AJ9: =AE9-AF9-AH9-AI9 -> 17192353 | AK9: =Inputs!$D$63-(A9-1) -> 57 | AL9: =IF(AK9<=0,0,IF(A9=1,Inputs!$B$63,AQ8)) -> 21075079 | AM9: =AL9*Inputs!$B$9 -> 53426.351 | AN9: =(AL9-AM9)*Inputs!$C$63/12 -> 167297.32 | AO9: =IF(AK9<=0,0,IF(AK9=1,AL9-AM9,MIN((AL9-AM9)*(Inputs!$C$63/12)/(1-(1+Inputs!$C$63/12)^(-AK9))-AN9,AL9-AM9))) -> 292895.68 | AP9: =(AL9-AM9-AO9)*Inputs!$B$10 -> 181202.73 | AQ9: =AL9-AM9-AO9-AP9 -> 20547555 | AR9: =Inputs!$D$64-(A9-1) -> 69 | AS9: =IF(AR9<=0,0,IF(A9=1,Inputs!$B$64,AX8)) -> 32969146 | AT9: =AS9*Inputs!$B$9 -> 83578.389 | AU9: =(AS9-AT9)*Inputs!$C$64/12 -> 268565.47 | AV9: =IF(AR9<=0,0,IF(AR9=1,AS9-AT9,MIN((AS9-AT9)*(Inputs!$C$64/12)/(1-(1+Inputs!$C$64/12)^(-AR9))-AU9,AS9-AT9))) -> 356757.92 | AW9: =(AS9-AT9-AV9)*Inputs!$B$10 -> 284354.2 | AX9: =AS9-AT9-AV9-AW9 -> 32244456 | AY9: =Inputs!$D$65-(A9-1) -> 69 | AZ9: =IF(AY9<=0,0,IF(A9=1,Inputs!$B$65,BE8)) -> 34110136 | BA9: =AZ9*Inputs!$B$9 -> 86470.852 | BB9: =(AZ9-BA9)*Inputs!$C$65/12 -> 292036.46 | BC9: =IF(AY9<=0,0,IF(AY9=1,AZ9-BA9,MIN((AZ9-BA9)*(Inputs!$C$65/12)/(1-(1+Inputs!$C$65/12)^(-AY9))-BB9,AZ9-BA9))) -> 363460.76 | BD9: =(AZ9-BA9-BC9)*Inputs!$B$10 -> 294244.41 | BE9: =AZ9-BA9-BC9-BD9 -> 33365960 | BF9: =Inputs!$D$66-(A9-1) -> 81 | BG9: =IF(BF9<=0,0,IF(A9=1,Inputs!$B$66,BL8)) -> 34039903 | BH9: =BG9*Inputs!$B$9 -> 86292.809 | BI9: =(BG9-BH9)*Inputs!$C$66/12 -> 298508.82 | BJ9: =IF(BF9<=0,0,IF(BF9=1,BG9-BH9,MIN((BG9-BH9)*(Inputs!$C$66/12)/(1-(1+Inputs!$C$66/12)^(-BF9))-BI9,BG9-BH9))) -> 289257.11 | BK9: =(BG9-BH9-BJ9)*Inputs!$B$10 -> 294280.68 | BL9: =BG9-BH9-BJ9-BK9 -> 33370072 | BM9: =Inputs!$D$67-(A9-1) -> 81 | BN9: =IF(BM9<=0,0,IF(A9=1,Inputs!$B$67,BS8)) -> 44621706 | BO9: =BN9*Inputs!$B$9 -> 113118.19 | BP9: =(BN9-BO9)*Inputs!$C$67/12 -> 409849.91 | BQ9: =IF(BM9<=0,0,IF(BM9=1,BN9-BO9,MIN((BN9-BO9)*(Inputs!$C$67/12)/(1-(1+Inputs!$C$67/12)^(-BM9))-BP9,BN9-BO9))) -> 372218.05 | BR9: =(BN9-BO9-BQ9)*Inputs!$B$10 -> 385822.97 | BS9: =BN9-BO9-BQ9-BR9 -> 43750547 | BT9: =C9+J9+Q9+X9+AE9+AL9+AS9+AZ9+BG9+BN9 -> 3.7047192e+08 | BU9: =D9+K9+R9+Y9+AF9+AM9+AT9+BA9+BH9+BO9 -> 939164.33 | BV9: =E9+L9+S9+Z9+AG9+AN9+AU9+BB9+BI9+BP9 -> 2824199 | BW9: =F9+M9+T9+AA9+AH9+AO9+AV9+BC9+BJ9+BQ9 -> 5456165.7 | BX9: =G9+N9+U9+AB9+AI9+AP9+AW9+BD9+BK9+BR9 -> 3182615.9 | BY9: =H9+O9+V9+AC9+AJ9+AQ9+AX9+BE9+BL9+BS9 -> 3.6089397e+08 | BZ9: =IF(A9>Inputs!$B$7,(1-Inputs!$B$6)*INDEX($BU$6:$BU$125,A9-Inputs!$B$7),0) -> 0 | CA9: =CA8+(1-Inputs!$B$6)*BU9-BZ9 -> 2343413.8 | CB9: =BY9+CA9 -> 3.6323739e+08 | CC9: =BV9+BW9+BX9+BZ9 -> 11462981 | CD9: =CD8+BU9-BZ9 -> 3905689.6
A10: =ROW()-5 -> 5 | B10: =Inputs!$D$58-(A10-1) -> 32 | C10: =IF(B10<=0,0,IF(A10=1,Inputs!$B$58,H9)) -> 33522558 | D10: =C10*Inputs!$B$9 -> 84981.315 | E10: =(C10-D10)*Inputs!$C$58/12 -> 203411.93 | F10: =IF(B10<=0,0,IF(B10=1,C10-D10,MIN((C10-D10)*(Inputs!$C$58/12)/(1-(1+Inputs!$C$58/12)^(-B10))-E10,C10-D10))) -> 949681.16 | G10: =(C10-D10-F10)*Inputs!$B$10 -> 283996.55 | H10: =C10-D10-F10-G10 -> 32203899 | I10: =Inputs!$D$59-(A10-1) -> 44 | J10: =IF(I10<=0,0,IF(A10=1,Inputs!$B$59,O9)) -> 66964543 | K10: =J10*Inputs!$B$9 -> 169758.37 | L10: =(J10-K10)*Inputs!$C$59/12 -> 434166.1 | M10: =IF(I10<=0,0,IF(I10=1,J10-K10,MIN((J10-K10)*(Inputs!$C$59/12)/(1-(1+Inputs!$C$59/12)^(-I10))-L10,J10-K10))) -> 1316208.8 | N10: =(J10-K10-M10)*Inputs!$B$10 -> 572388.24 | O10: =J10-K10-M10-N10 -> 64906188 | P10: =Inputs!$D$60-(A10-1) -> 44 | Q10: =IF(P10<=0,0,IF(A10=1,Inputs!$B$60,V9)) -> 19172311 | R10: =Q10*Inputs!$B$9 -> 48602.741 | S10: =(Q10-R10)*Inputs!$C$60/12 -> 132272.32 | T10: =IF(P10<=0,0,IF(P10=1,Q10-R10,MIN((Q10-R10)*(Inputs!$C$60/12)/(1-(1+Inputs!$C$60/12)^(-P10))-S10,Q10-R10))) -> 373332.86 | U10: =(Q10-R10-T10)*Inputs!$B$10 -> 163908.49 | V10: =Q10-R10-T10-U10 -> 18586467 | W10: =Inputs!$D$61-(A10-1) -> 56 | X10: =IF(W10<=0,0,IF(A10=1,Inputs!$B$61,AC9)) -> 60763619 | Y10: =X10*Inputs!$B$9 -> 154038.73 | Z10: =(X10-Y10)*Inputs!$C$61/12 -> 444470.25 | AA10: =IF(W10<=0,0,IF(W10=1,X10-Y10,MIN((X10-Y10)*(Inputs!$C$61/12)/(1-(1+Inputs!$C$61/12)^(-W10))-Z10,X10-Y10))) -> 879155.59 | AB10: =(X10-Y10-AA10)*Inputs!$B$10 -> 522140.13 | AC10: =X10-Y10-AA10-AB10 -> 59208284 | AD10: =Inputs!$D$62-(A10-1) -> 56 | AE10: =IF(AD10<=0,0,IF(A10=1,Inputs!$B$62,AJ9)) -> 17192353 | AF10: =AE10*Inputs!$B$9 -> 43583.45 | AG10: =(AE10-AF10)*Inputs!$C$62/12 -> 132902.96 | AH10: =IF(AD10<=0,0,IF(AD10=1,AE10-AF10,MIN((AE10-AF10)*(Inputs!$C$62/12)/(1-(1+Inputs!$C$62/12)^(-AD10))-AG10,AE10-AF10))) -> 245734.93 | AI10: =(AE10-AF10-AH10)*Inputs!$B$10 -> 147759.75 | AJ10: =AE10-AF10-AH10-AI10 -> 16755275 | AK10: =Inputs!$D$63-(A10-1) -> 56 | AL10: =IF(AK10<=0,0,IF(A10=1,Inputs!$B$63,AQ9)) -> 20547555 | AM10: =AL10*Inputs!$B$9 -> 52089.05 | AN10: =(AL10-AM10)*Inputs!$C$63/12 -> 163109.75 | AO10: =IF(AK10<=0,0,IF(AK10=1,AL10-AM10,MIN((AL10-AM10)*(Inputs!$C$63/12)/(1-(1+Inputs!$C$63/12)^(-AK10))-AN10,AL10-AM10))) -> 291904.01 | AP10: =(AL10-AM10-AO10)*Inputs!$B$10 -> 176611.68 | AQ10: =AL10-AM10-AO10-AP10 -> 20026950 | AR10: =Inputs!$D$64-(A10-1) -> 68 | AS10: =IF(AR10<=0,0,IF(A10=1,Inputs!$B$64,AX9)) -> 32244456 | AT10: =AS10*Inputs!$B$9 -> 81741.263 | AU10: =(AS10-AT10)*Inputs!$C$64/12 -> 262662.17 | AV10: =IF(AR10<=0,0,IF(AR10=1,AS10-AT10,MIN((AS10-AT10)*(Inputs!$C$64/12)/(1-(1+Inputs!$C$64/12)^(-AR10))-AU10,AS10-AT10))) -> 355623.52 | AW10: =(AS10-AT10-AV10)*Inputs!$B$10 -> 278045.22 | AX10: =AS10-AT10-AV10-AW10 -> 31529046 | AY10: =Inputs!$D$65-(A10-1) -> 68 | AZ10: =IF(AY10<=0,0,IF(A10=1,Inputs!$B$65,BE9)) -> 33365960 | BA10: =AZ10*Inputs!$B$9 -> 84584.33 | BB10: =(AZ10-BA10)*Inputs!$C$65/12 -> 285665.14 | BC10: =IF(AY10<=0,0,IF(AY10=1,AZ10-BA10,MIN((AZ10-BA10)*(Inputs!$C$65/12)/(1-(1+Inputs!$C$65/12)^(-AY10))-BB10,AZ10-BA10))) -> 362454.79 | BD10: =(AZ10-BA10-BC10)*Inputs!$B$10 -> 287764.4 | BE10: =AZ10-BA10-BC10-BD10 -> 32631156 | BF10: =Inputs!$D$66-(A10-1) -> 80 | BG10: =IF(BF10<=0,0,IF(A10=1,Inputs!$B$66,BL9)) -> 33370072 | BH10: =BG10*Inputs!$B$9 -> 84594.756 | BI10: =(BG10-BH10)*Inputs!$C$66/12 -> 292634.82 | BJ10: =IF(BF10<=0,0,IF(BF10=1,BG10-BH10,MIN((BG10-BH10)*(Inputs!$C$66/12)/(1-(1+Inputs!$C$66/12)^(-BF10))-BI10,BG10-BH10))) -> 288516.1 | BK10: =(BG10-BH10-BJ10)*Inputs!$B$10 -> 288446.6 | BL10: =BG10-BH10-BJ10-BK10 -> 32708515 | BM10: =Inputs!$D$67-(A10-1) -> 80 | BN10: =IF(BM10<=0,0,IF(A10=1,Inputs!$B$67,BS9)) -> 43750547 | BO10: =BN10*Inputs!$B$9 -> 110909.76 | BP10: =(BN10-BO10)*Inputs!$C$67/12 -> 401848.32 | BQ10: =IF(BM10<=0,0,IF(BM10=1,BN10-BO10,MIN((BN10-BO10)*(Inputs!$C$67/12)/(1-(1+Inputs!$C$67/12)^(-BM10))-BP10,BN10-BO10))) -> 371417.86 | BR10: =(BN10-BO10-BQ10)*Inputs!$B$10 -> 378233.94 | BS10: =BN10-BO10-BQ10-BR10 -> 42889985 | BT10: =C10+J10+Q10+X10+AE10+AL10+AS10+AZ10+BG10+BN10 -> 3.6089397e+08 | BU10: =D10+K10+R10+Y10+AF10+AM10+AT10+BA10+BH10+BO10 -> 914883.77 | BV10: =E10+L10+S10+Z10+AG10+AN10+AU10+BB10+BI10+BP10 -> 2753143.8 | BW10: =F10+M10+T10+AA10+AH10+AO10+AV10+BC10+BJ10+BQ10 -> 5434029.6 | BX10: =G10+N10+U10+AB10+AI10+AP10+AW10+BD10+BK10+BR10 -> 3099295 | BY10: =H10+O10+V10+AC10+AJ10+AQ10+AX10+BE10+BL10+BS10 -> 3.5144577e+08 | BZ10: =IF(A10>Inputs!$B$7,(1-Inputs!$B$6)*INDEX($BU$6:$BU$125,A10-Inputs!$B$7),0) -> 0 | CA10: =CA9+(1-Inputs!$B$6)*BU10-BZ10 -> 2892344 | CB10: =BY10+CA10 -> 3.5433811e+08 | CC10: =BV10+BW10+BX10+BZ10 -> 11286468 | CD10: =CD9+BU10-BZ10 -> 4820573.4
A11: =ROW()-5 -> 6 | B11: =Inputs!$D$58-(A11-1) -> 31 | C11: =IF(B11<=0,0,IF(A11=1,Inputs!$B$58,H10)) -> 32203899 | D11: =C11*Inputs!$B$9 -> 81638.451 | E11: =(C11-D11)*Inputs!$C$58/12 -> 195410.42 | F11: =IF(B11<=0,0,IF(B11=1,C11-D11,MIN((C11-D11)*(Inputs!$C$58/12)/(1-(1+Inputs!$C$58/12)^(-B11))-E11,C11-D11))) -> 944705.18 | G11: =(C11-D11-F11)*Inputs!$B$10 -> 272542.06 | H11: =C11-D11-F11-G11 -> 30905014 | I11: =Inputs!$D$59-(A11-1) -> 43 | J11: =IF(I11<=0,0,IF(A11=1,Inputs!$B$59,O10)) -> 64906188 | K11: =J11*Inputs!$B$9 -> 164540.34 | L11: =(J11-K11)*Inputs!$C$59/12 -> 420820.71 | M11: =IF(I11<=0,0,IF(I11=1,J11-K11,MIN((J11-K11)*(Inputs!$C$59/12)/(1-(1+Inputs!$C$59/12)^(-I11))-L11,J11-K11))) -> 1309854.6 | N11: =(J11-K11-M11)*Inputs!$B$10 -> 554496.06 | O11: =J11-K11-M11-N11 -> 62877297 | P11: =Inputs!$D$60-(A11-1) -> 43 | Q11: =IF(P11<=0,0,IF(A11=1,Inputs!$B$60,V10)) -> 18586467 | R11: =Q11*Inputs!$B$9 -> 47117.598 | S11: =(Q11-R11)*Inputs!$C$60/12 -> 128230.5 | T11: =IF(P11<=0,0,IF(P11=1,Q11-R11,MIN((Q11-R11)*(Inputs!$C$60/12)/(1-(1+Inputs!$C$60/12)^(-P11))-S11,Q11-R11))) -> 371684.34 | U11: =(Q11-R11-T11)*Inputs!$B$10 -> 158814.66 | V11: =Q11-R11-T11-U11 -> 18008851 | W11: =Inputs!$D$61-(A11-1) -> 55 | X11: =IF(W11<=0,0,IF(A11=1,Inputs!$B$61,AC10)) -> 59208284 | Y11: =X11*Inputs!$B$9 -> 150095.88 | Z11: =(X11-Y11)*Inputs!$C$61/12 -> 433093.38 | AA11: =IF(W11<=0,0,IF(W11=1,X11-Y11,MIN((X11-Y11)*(Inputs!$C$61/12)/(1-(1+Inputs!$C$61/12)^(-W11))-Z11,X11-Y11))) -> 875635.72 | AB11: =(X11-Y11-AA11)*Inputs!$B$10 -> 508609.24 | AC11: =X11-Y11-AA11-AB11 -> 57673944 | AD11: =Inputs!$D$62-(A11-1) -> 55 | AE11: =IF(AD11<=0,0,IF(A11=1,Inputs!$B$62,AJ10)) -> 16755275 | AF11: =AE11*Inputs!$B$9 -> 42475.436 | AG11: =(AE11-AF11)*Inputs!$C$62/12 -> 129524.19 | AH11: =IF(AD11<=0,0,IF(AD11=1,AE11-AF11,MIN((AE11-AF11)*(Inputs!$C$62/12)/(1-(1+Inputs!$C$62/12)^(-AD11))-AG11,AE11-AF11))) -> 244852.31 | AI11: =(AE11-AF11-AH11)*Inputs!$B$10 -> 143956.38 | AJ11: =AE11-AF11-AH11-AI11 -> 16323990 | AK11: =Inputs!$D$63-(A11-1) -> 55 | AL11: =IF(AK11<=0,0,IF(A11=1,Inputs!$B$63,AQ10)) -> 20026950 | AM11: =AL11*Inputs!$B$9 -> 50769.292 | AN11: =(AL11-AM11)*Inputs!$C$63/12 -> 158977.1 | AO11: =IF(AK11<=0,0,IF(AK11=1,AL11-AM11,MIN((AL11-AM11)*(Inputs!$C$63/12)/(1-(1+Inputs!$C$63/12)^(-AK11))-AN11,AL11-AM11))) -> 290915.7 | AP11: =(AL11-AM11-AO11)*Inputs!$B$10 -> 172080.93 | AQ11: =AL11-AM11-AO11-AP11 -> 19513184 | AR11: =Inputs!$D$64-(A11-1) -> 67 | AS11: =IF(AR11<=0,0,IF(A11=1,Inputs!$B$64,AX10)) -> 31529046 | AT11: =AS11*Inputs!$B$9 -> 79927.664 | AU11: =(AS11-AT11)*Inputs!$C$64/12 -> 256834.47 | AV11: =IF(AR11<=0,0,IF(AR11=1,AS11-AT11,MIN((AS11-AT11)*(Inputs!$C$64/12)/(1-(1+Inputs!$C$64/12)^(-AR11))-AU11,AS11-AT11))) -> 354492.72 | AW11: =(AS11-AT11-AV11)*Inputs!$B$10 -> 271817.12 | AX11: =AS11-AT11-AV11-AW11 -> 30822808 | AY11: =Inputs!$D$65-(A11-1) -> 67 | AZ11: =IF(AY11<=0,0,IF(A11=1,Inputs!$B$65,BE10)) -> 32631156 | BA11: =AZ11*Inputs!$B$9 -> 82721.567 | BB11: =(AZ11-BA11)*Inputs!$C$65/12 -> 279374.06 | BC11: =IF(AY11<=0,0,IF(AY11=1,AZ11-BA11,MIN((AZ11-BA11)*(Inputs!$C$65/12)/(1-(1+Inputs!$C$65/12)^(-AY11))-BB11,AZ11-BA11))) -> 361451.6 | BD11: =(AZ11-BA11-BC11)*Inputs!$B$10 -> 281366.08 | BE11: =AZ11-BA11-BC11-BD11 -> 31905617 | BF11: =Inputs!$D$66-(A11-1) -> 79 | BG11: =IF(BF11<=0,0,IF(A11=1,Inputs!$B$66,BL10)) -> 32708515 | BH11: =BG11*Inputs!$B$9 -> 82917.676 | BI11: =(BG11-BH11)*Inputs!$C$66/12 -> 286833.38 | BJ11: =IF(BF11<=0,0,IF(BF11=1,BG11-BH11,MIN((BG11-BH11)*(Inputs!$C$66/12)/(1-(1+Inputs!$C$66/12)^(-BF11))-BI11,BG11-BH11))) -> 287776.99 | BK11: =(BG11-BH11-BJ11)*Inputs!$B$10 -> 282684.64 | BL11: =BG11-BH11-BJ11-BK11 -> 32055136 | BM11: =Inputs!$D$67-(A11-1) -> 79 | BN11: =IF(BM11<=0,0,IF(A11=1,Inputs!$B$67,BS10)) -> 42889985 | BO11: =BN11*Inputs!$B$9 -> 108728.2 | BP11: =(BN11-BO11)*Inputs!$C$67/12 -> 393944.07 | BQ11: =IF(BM11<=0,0,IF(BM11=1,BN11-BO11,MIN((BN11-BO11)*(Inputs!$C$67/12)/(1-(1+Inputs!$C$67/12)^(-BM11))-BP11,BN11-BO11))) -> 370619.38 | BR11: =(BN11-BO11-BQ11)*Inputs!$B$10 -> 370737.29 | BS11: =BN11-BO11-BQ11-BR11 -> 42039900 | BT11: =C11+J11+Q11+X11+AE11+AL11+AS11+AZ11+BG11+BN11 -> 3.5144577e+08 | BU11: =D11+K11+R11+Y11+AF11+AM11+AT11+BA11+BH11+BO11 -> 890932.1 | BV11: =E11+L11+S11+Z11+AG11+AN11+AU11+BB11+BI11+BP11 -> 2683042.3 | BW11: =F11+M11+T11+AA11+AH11+AO11+AV11+BC11+BJ11+BQ11 -> 5411988.6 | BX11: =G11+N11+U11+AB11+AI11+AP11+AW11+BD11+BK11+BR11 -> 3017104.5 | BY11: =H11+O11+V11+AC11+AJ11+AQ11+AX11+BE11+BL11+BS11 -> 3.4212574e+08 | BZ11: =IF(A11>Inputs!$B$7,(1-Inputs!$B$6)*INDEX($BU$6:$BU$125,A11-Inputs!$B$7),0) -> 0 | CA11: =CA10+(1-Inputs!$B$6)*BU11-BZ11 -> 3426903.3 | CB11: =BY11+CA11 -> 3.4555264e+08 | CC11: =BV11+BW11+BX11+BZ11 -> 11112135 | CD11: =CD10+BU11-BZ11 -> 5711505.5
A12: =ROW()-5 -> 7 | B12: =Inputs!$D$58-(A12-1) -> 30 | C12: =IF(B12<=0,0,IF(A12=1,Inputs!$B$58,H11)) -> 30905014 | D12: =C12*Inputs!$B$9 -> 78345.712 | E12: =(C12-D12)*Inputs!$C$58/12 -> 187528.9 | F12: =IF(B12<=0,0,IF(B12=1,C12-D12,MIN((C12-D12)*(Inputs!$C$58/12)/(1-(1+Inputs!$C$58/12)^(-B12))-E12,C12-D12))) -> 939755.27 | G12: =(C12-D12-F12)*Inputs!$B$10 -> 261259.76 | H12: =C12-D12-F12-G12 -> 29625653 | I12: =Inputs!$D$59-(A12-1) -> 42 | J12: =IF(I12<=0,0,IF(A12=1,Inputs!$B$59,O11)) -> 62877297 | K12: =J12*Inputs!$B$9 -> 159397 | L12: =(J12-K12)*Inputs!$C$59/12 -> 407666.35 | M12: =IF(I12<=0,0,IF(I12=1,J12-K12,MIN((J12-K12)*(Inputs!$C$59/12)/(1-(1+Inputs!$C$59/12)^(-I12))-L12,J12-K12))) -> 1303531.1 | N12: =(J12-K12-M12)*Inputs!$B$10 -> 536860.52 | O12: =J12-K12-M12-N12 -> 60877508 | P12: =Inputs!$D$60-(A12-1) -> 42 | Q12: =IF(P12<=0,0,IF(A12=1,Inputs!$B$60,V11)) -> 18008851 | R12: =Q12*Inputs!$B$9 -> 45653.312 | S12: =(Q12-R12)*Inputs!$C$60/12 -> 124245.45 | T12: =IF(P12<=0,0,IF(P12=1,Q12-R12,MIN((Q12-R12)*(Inputs!$C$60/12)/(1-(1+Inputs!$C$60/12)^(-P12))-S12,Q12-R12))) -> 370043.11 | U12: =(Q12-R12-T12)*Inputs!$B$10 -> 153792.51 | V12: =Q12-R12-T12-U12 -> 17439362 | W12: =Inputs!$D$61-(A12-1) -> 54 | X12: =IF(W12<=0,0,IF(A12=1,Inputs!$B$61,AC11)) -> 57673944 | Y12: =X12*Inputs!$B$9 -> 146206.25 | Z12: =(X12-Y12)*Inputs!$C$61/12 -> 421870.07 | AA12: =IF(W12<=0,0,IF(W12=1,X12-Y12,MIN((X12-Y12)*(Inputs!$C$61/12)/(1-(1+Inputs!$C$61/12)^(-W12))-Z12,X12-Y12))) -> 872129.94 | AB12: =(X12-Y12-AA12)*Inputs!$B$10 -> 495261.28 | AC12: =X12-Y12-AA12-AB12 -> 56160346 | AD12: =Inputs!$D$62-(A12-1) -> 54 | AE12: =IF(AD12<=0,0,IF(A12=1,Inputs!$B$62,AJ11)) -> 16323990 | AF12: =AE12*Inputs!$B$9 -> 41382.109 | AG12: =(AE12-AF12)*Inputs!$C$62/12 -> 126190.21 | AH12: =IF(AD12<=0,0,IF(AD12=1,AE12-AF12,MIN((AE12-AF12)*(Inputs!$C$62/12)/(1-(1+Inputs!$C$62/12)^(-AD12))-AG12,AE12-AF12))) -> 243972.87 | AI12: =(AE12-AF12-AH12)*Inputs!$B$10 -> 140203.51 | AJ12: =AE12-AF12-AH12-AI12 -> 15898432 | AK12: =Inputs!$D$63-(A12-1) -> 54 | AL12: =IF(AK12<=0,0,IF(A12=1,Inputs!$B$63,AQ11)) -> 19513184 | AM12: =AL12*Inputs!$B$9 -> 49466.87 | AN12: =(AL12-AM12)*Inputs!$C$63/12 -> 154898.75 | AO12: =IF(AK12<=0,0,IF(AK12=1,AL12-AM12,MIN((AL12-AM12)*(Inputs!$C$63/12)/(1-(1+Inputs!$C$63/12)^(-AK12))-AN12,AL12-AM12))) -> 289930.74 | AP12: =(AL12-AM12-AO12)*Inputs!$B$10 -> 167609.78 | AQ12: =AL12-AM12-AO12-AP12 -> 19006177 | AR12: =Inputs!$D$64-(A12-1) -> 66 | AS12: =IF(AR12<=0,0,IF(A12=1,Inputs!$B$64,AX11)) -> 30822808 | AT12: =AS12*Inputs!$B$9 -> 78137.318 | AU12: =(AS12-AT12)*Inputs!$C$64/12 -> 251081.48 | AV12: =IF(AR12<=0,0,IF(AR12=1,AS12-AT12,MIN((AS12-AT12)*(Inputs!$C$64/12)/(1-(1+Inputs!$C$64/12)^(-AR12))-AU12,AS12-AT12))) -> 353365.53 | AW12: =(AS12-AT12-AV12)*Inputs!$B$10 -> 265668.97 | AX12: =AS12-AT12-AV12-AW12 -> 30125637 | AY12: =Inputs!$D$65-(A12-1) -> 66 | AZ12: =IF(AY12<=0,0,IF(A12=1,Inputs!$B$65,BE11)) -> 31905617 | BA12: =AZ12*Inputs!$B$9 -> 80882.29 | BB12: =(AZ12-BA12)*Inputs!$C$65/12 -> 273162.31 | BC12: =IF(AY12<=0,0,IF(AY12=1,AZ12-BA12,MIN((AZ12-BA12)*(Inputs!$C$65/12)/(1-(1+Inputs!$C$65/12)^(-AY12))-BB12,AZ12-BA12))) -> 360451.19 | BD12: =(AZ12-BA12-BC12)*Inputs!$B$10 -> 275048.53 | BE12: =AZ12-BA12-BC12-BD12 -> 31189235 | BF12: =Inputs!$D$66-(A12-1) -> 78 | BG12: =IF(BF12<=0,0,IF(A12=1,Inputs!$B$66,BL11)) -> 32055136 | BH12: =BG12*Inputs!$B$9 -> 81261.327 | BI12: =(BG12-BH12)*Inputs!$C$66/12 -> 281103.65 | BJ12: =IF(BF12<=0,0,IF(BF12=1,BG12-BH12,MIN((BG12-BH12)*(Inputs!$C$66/12)/(1-(1+Inputs!$C$66/12)^(-BF12))-BI12,BG12-BH12))) -> 287039.77 | BK12: =(BG12-BH12-BJ12)*Inputs!$B$10 -> 276993.98 | BL12: =BG12-BH12-BJ12-BK12 -> 31409841 | BM12: =Inputs!$D$67-(A12-1) -> 78 | BN12: =IF(BM12<=0,0,IF(A12=1,Inputs!$B$67,BS11)) -> 42039900 | BO12: =BN12*Inputs!$B$9 -> 106573.19 | BP12: =(BN12-BO12)*Inputs!$C$67/12 -> 386136.05 | BQ12: =IF(BM12<=0,0,IF(BM12=1,BN12-BO12,MIN((BN12-BO12)*(Inputs!$C$67/12)/(1-(1+Inputs!$C$67/12)^(-BM12))-BP12,BN12-BO12))) -> 369822.62 | BR12: =(BN12-BO12-BQ12)*Inputs!$B$10 -> 363331.99 | BS12: =BN12-BO12-BQ12-BR12 -> 41200172 | BT12: =C12+J12+Q12+X12+AE12+AL12+AS12+AZ12+BG12+BN12 -> 3.4212574e+08 | BU12: =D12+K12+R12+Y12+AF12+AM12+AT12+BA12+BH12+BO12 -> 867305.38 | BV12: =E12+L12+S12+Z12+AG12+AN12+AU12+BB12+BI12+BP12 -> 2613883.2 | BW12: =F12+M12+T12+AA12+AH12+AO12+AV12+BC12+BJ12+BQ12 -> 5390042.1 | BX12: =G12+N12+U12+AB12+AI12+AP12+AW12+BD12+BK12+BR12 -> 2936030.8 | BY12: =H12+O12+V12+AC12+AJ12+AQ12+AX12+BE12+BL12+BS12 -> 3.3293236e+08 | BZ12: =IF(A12>Inputs!$B$7,(1-Inputs!$B$6)*INDEX($BU$6:$BU$125,A12-Inputs!$B$7),0) -> 608411.67 | CA12: =CA11+(1-Inputs!$B$6)*BU12-BZ12 -> 3338874.9 | CB12: =BY12+CA12 -> 3.3627124e+08 | CC12: =BV12+BW12+BX12+BZ12 -> 11548368 | CD12: =CD11+BU12-BZ12 -> 5970399.2
A13: =ROW()-5 -> 8 | B13: =Inputs!$D$58-(A13-1) -> 29 | C13: =IF(B13<=0,0,IF(A13=1,Inputs!$B$58,H12)) -> 29625653 | D13: =C13*Inputs!$B$9 -> 75102.471 | E13: =(C13-D13)*Inputs!$C$58/12 -> 179765.85 | F13: =IF(B13<=0,0,IF(B13=1,C13-D13,MIN((C13-D13)*(Inputs!$C$58/12)/(1-(1+Inputs!$C$58/12)^(-B13))-E13,C13-D13))) -> 934831.3 | G13: =(C13-D13-F13)*Inputs!$B$10 -> 250147.48 | H13: =C13-D13-F13-G13 -> 28365572 | I13: =Inputs!$D$59-(A13-1) -> 41 | J13: =IF(I13<=0,0,IF(A13=1,Inputs!$B$59,O12)) -> 60877508 | K13: =J13*Inputs!$B$9 -> 154327.44 | L13: =(J13-K13)*Inputs!$C$59/12 -> 394700.68 | M13: =IF(I13<=0,0,IF(I13=1,J13-K13,MIN((J13-K13)*(Inputs!$C$59/12)/(1-(1+Inputs!$C$59/12)^(-I13))-L13,J13-K13))) -> 1297238.1 | N13: =(J13-K13-M13)*Inputs!$B$10 -> 519478.47 | O13: =J13-K13-M13-N13 -> 58906464 | P13: =Inputs!$D$60-(A13-1) -> 41 | Q13: =IF(P13<=0,0,IF(A13=1,Inputs!$B$60,V12)) -> 17439362 | R13: =Q13*Inputs!$B$9 -> 44209.63 | S13: =(Q13-R13)*Inputs!$C$60/12 -> 120316.47 | T13: =IF(P13<=0,0,IF(P13=1,Q13-R13,MIN((Q13-R13)*(Inputs!$C$60/12)/(1-(1+Inputs!$C$60/12)^(-P13))-S13,Q13-R13))) -> 368409.12 | U13: =(Q13-R13-T13)*Inputs!$B$10 -> 148841.16 | V13: =Q13-R13-T13-U13 -> 16877902 | W13: =Inputs!$D$61-(A13-1) -> 53 | X13: =IF(W13<=0,0,IF(A13=1,Inputs!$B$61,AC12)) -> 56160346 | Y13: =X13*Inputs!$B$9 -> 142369.21 | Z13: =(X13-Y13)*Inputs!$C$61/12 -> 410798.5 | AA13: =IF(W13<=0,0,IF(W13=1,X13-Y13,MIN((X13-Y13)*(Inputs!$C$61/12)/(1-(1+Inputs!$C$61/12)^(-W13))-Z13,X13-Y13))) -> 868638.19 | AB13: =(X13-Y13-AA13)*Inputs!$B$10 -> 482094.06 | AC13: =X13-Y13-AA13-AB13 -> 54667245 | AD13: =Inputs!$D$62-(A13-1) -> 53 | AE13: =IF(AD13<=0,0,IF(A13=1,Inputs!$B$62,AJ12)) -> 15898432 | AF13: =AE13*Inputs!$B$9 -> 40303.298 | AG13: =(AE13-AF13)*Inputs!$C$62/12 -> 122900.5 | AH13: =IF(AD13<=0,0,IF(AD13=1,AE13-AF13,MIN((AE13-AF13)*(Inputs!$C$62/12)/(1-(1+Inputs!$C$62/12)^(-AD13))-AG13,AE13-AF13))) -> 243096.59 | AI13: =(AE13-AF13-AH13)*Inputs!$B$10 -> 136500.54 | AJ13: =AE13-AF13-AH13-AI13 -> 15478532 | AK13: =Inputs!$D$63-(A13-1) -> 53 | AL13: =IF(AK13<=0,0,IF(A13=1,Inputs!$B$63,AQ12)) -> 19006177 | AM13: =AL13*Inputs!$B$9 -> 48181.582 | AN13: =(AL13-AM13)*Inputs!$C$63/12 -> 150874.04 | AO13: =IF(AK13<=0,0,IF(AK13=1,AL13-AM13,MIN((AL13-AM13)*(Inputs!$C$63/12)/(1-(1+Inputs!$C$63/12)^(-AK13))-AN13,AL13-AM13))) -> 288949.11 | AP13: =(AL13-AM13-AO13)*Inputs!$B$10 -> 163197.54 | AQ13: =AL13-AM13-AO13-AP13 -> 18505848 | AR13: =Inputs!$D$64-(A13-1) -> 65 | AS13: =IF(AR13<=0,0,IF(A13=1,Inputs!$B$64,AX12)) -> 30125637 | AT13: =AS13*Inputs!$B$9 -> 76369.953 | AU13: =(AS13-AT13)*Inputs!$C$64/12 -> 245402.34 | AV13: =IF(AR13<=0,0,IF(AR13=1,AS13-AT13,MIN((AS13-AT13)*(Inputs!$C$64/12)/(1-(1+Inputs!$C$64/12)^(-AR13))-AU13,AS13-AT13))) -> 352241.92 | AW13: =(AS13-AT13-AV13)*Inputs!$B$10 -> 259599.84 | AX13: =AS13-AT13-AV13-AW13 -> 29437425 | AY13: =Inputs!$D$65-(A13-1) -> 65 | AZ13: =IF(AY13<=0,0,IF(A13=1,Inputs!$B$65,BE12)) -> 31189235 | BA13: =AZ13*Inputs!$B$9 -> 79066.227 | BB13: =(AZ13-BA13)*Inputs!$C$65/12 -> 267028.95 | BC13: =IF(AY13<=0,0,IF(AY13=1,AZ13-BA13,MIN((AZ13-BA13)*(Inputs!$C$65/12)/(1-(1+Inputs!$C$65/12)^(-AY13))-BB13,AZ13-BA13))) -> 359453.54 | BD13: =(AZ13-BA13-BC13)*Inputs!$B$10 -> 268810.79 | BE13: =AZ13-BA13-BC13-BD13 -> 30481904 | BF13: =Inputs!$D$66-(A13-1) -> 77 | BG13: =IF(BF13<=0,0,IF(A13=1,Inputs!$B$66,BL12)) -> 31409841 | BH13: =BG13*Inputs!$B$9 -> 79625.473 | BI13: =(BG13-BH13)*Inputs!$C$66/12 -> 275444.81 | BJ13: =IF(BF13<=0,0,IF(BF13=1,BG13-BH13,MIN((BG13-BH13)*(Inputs!$C$66/12)/(1-(1+Inputs!$C$66/12)^(-BF13))-BI13,BG13-BH13))) -> 286304.43 | BK13: =(BG13-BH13-BJ13)*Inputs!$B$10 -> 271373.79 | BL13: =BG13-BH13-BJ13-BK13 -> 30772537 | BM13: =Inputs!$D$67-(A13-1) -> 77 | BN13: =IF(BM13<=0,0,IF(A13=1,Inputs!$B$67,BS12)) -> 41200172 | BO13: =BN13*Inputs!$B$9 -> 104444.44 | BP13: =(BN13-BO13)*Inputs!$C$67/12 -> 378423.16 | BQ13: =IF(BM13<=0,0,IF(BM13=1,BN13-BO13,MIN((BN13-BO13)*(Inputs!$C$67/12)/(1-(1+Inputs!$C$67/12)^(-BM13))-BP13,BN13-BO13))) -> 369027.58 | BR13: =(BN13-BO13-BQ13)*Inputs!$B$10 -> 356016.97 | BS13: =BN13-BO13-BQ13-BR13 -> 40370683 | BT13: =C13+J13+Q13+X13+AE13+AL13+AS13+AZ13+BG13+BN13 -> 3.3293236e+08 | BU13: =D13+K13+R13+Y13+AF13+AM13+AT13+BA13+BH13+BO13 -> 843999.72 | BV13: =E13+L13+S13+Z13+AG13+AN13+AU13+BB13+BI13+BP13 -> 2545655.3 | BW13: =F13+M13+T13+AA13+AH13+AO13+AV13+BC13+BJ13+BQ13 -> 5368189.9 | BX13: =G13+N13+U13+AB13+AI13+AP13+AW13+BD13+BK13+BR13 -> 2856060.6 | BY13: =H13+O13+V13+AC13+AJ13+AQ13+AX13+BE13+BL13+BS13 -> 3.2386411e+08 | BZ13: =IF(A13>Inputs!$B$7,(1-Inputs!$B$6)*INDEX($BU$6:$BU$125,A13-Inputs!$B$7),0) -> 593236.87 | CA13: =CA12+(1-Inputs!$B$6)*BU13-BZ13 -> 3252037.8 | CB13: =BY13+CA13 -> 3.2711615e+08 | CC13: =BV13+BW13+BX13+BZ13 -> 11363143 | CD13: =CD12+BU13-BZ13 -> 6221162.1
A14: =ROW()-5 -> 9 | B14: =Inputs!$D$58-(A14-1) -> 28 | C14: =IF(B14<=0,0,IF(A14=1,Inputs!$B$58,H13)) -> 28365572 | D14: =C14*Inputs!$B$9 -> 71908.103 | E14: =(C14-D14)*Inputs!$C$58/12 -> 172119.79 | F14: =IF(B14<=0,0,IF(B14=1,C14-D14,MIN((C14-D14)*(Inputs!$C$58/12)/(1-(1+Inputs!$C$58/12)^(-B14))-E14,C14-D14))) -> 929933.13 | G14: =(C14-D14-F14)*Inputs!$B$10 -> 239203.09 | H14: =C14-D14-F14-G14 -> 27124527 | I14: =Inputs!$D$59-(A14-1) -> 40 | J14: =IF(I14<=0,0,IF(A14=1,Inputs!$B$59,O13)) -> 58906464 | K14: =J14*Inputs!$B$9 -> 149330.75 | L14: =(J14-K14)*Inputs!$C$59/12 -> 381921.37 | M14: =IF(I14<=0,0,IF(I14=1,J14-K14,MIN((J14-K14)*(Inputs!$C$59/12)/(1-(1+Inputs!$C$59/12)^(-I14))-L14,J14-K14))) -> 1290975.5 | N14: =(J14-K14-M14)*Inputs!$B$10 -> 502346.8 | O14: =J14-K14-M14-N14 -> 56963811 | P14: =Inputs!$D$60-(A14-1) -> 40 | Q14: =IF(P14<=0,0,IF(A14=1,Inputs!$B$60,V13)) -> 16877902 | R14: =Q14*Inputs!$B$9 -> 42786.302 | S14: =(Q14-R14)*Inputs!$C$60/12 -> 116442.88 | T14: =IF(P14<=0,0,IF(P14=1,Q14-R14,MIN((Q14-R14)*(Inputs!$C$60/12)/(1-(1+Inputs!$C$60/12)^(-P14))-S14,Q14-R14))) -> 366782.34 | U14: =(Q14-R14-T14)*Inputs!$B$10 -> 143959.76 | V14: =Q14-R14-T14-U14 -> 16324373 | W14: =Inputs!$D$61-(A14-1) -> 52 | X14: =IF(W14<=0,0,IF(A14=1,Inputs!$B$61,AC13)) -> 54667245 | Y14: =X14*Inputs!$B$9 -> 138584.12 | Z14: =(X14-Y14)*Inputs!$C$61/12 -> 399876.84 | AA14: =IF(W14<=0,0,IF(W14=1,X14-Y14,MIN((X14-Y14)*(Inputs!$C$61/12)/(1-(1+Inputs!$C$61/12)^(-W14))-Z14,X14-Y14))) -> 865160.43 | AB14: =(X14-Y14-AA14)*Inputs!$B$10 -> 469105.44 | AC14: =X14-Y14-AA14-AB14 -> 53194395 | AD14: =Inputs!$D$62-(A14-1) -> 52 | AE14: =IF(AD14<=0,0,IF(A14=1,Inputs!$B$62,AJ13)) -> 15478532 | AF14: =AE14*Inputs!$B$9 -> 39238.83 | AG14: =(AE14-AF14)*Inputs!$C$62/12 -> 119654.52 | AH14: =IF(AD14<=0,0,IF(AD14=1,AE14-AF14,MIN((AE14-AF14)*(Inputs!$C$62/12)/(1-(1+Inputs!$C$62/12)^(-AD14))-AG14,AE14-AF14))) -> 242223.46 | AI14: =(AE14-AF14-AH14)*Inputs!$B$10 -> 132846.87 | AJ14: =AE14-AF14-AH14-AI14 -> 15064222 | AK14: =Inputs!$D$63-(A14-1) -> 52 | AL14: =IF(AK14<=0,0,IF(A14=1,Inputs!$B$63,AQ13)) -> 18505848 | AM14: =AL14*Inputs!$B$9 -> 46913.225 | AN14: =(AL14-AM14)*Inputs!$C$63/12 -> 146902.36 | AO14: =IF(AK14<=0,0,IF(AK14=1,AL14-AM14,MIN((AL14-AM14)*(Inputs!$C$63/12)/(1-(1+Inputs!$C$63/12)^(-AK14))-AN14,AL14-AM14))) -> 287970.81 | AP14: =(AL14-AM14-AO14)*Inputs!$B$10 -> 158843.5 | AQ14: =AL14-AM14-AO14-AP14 -> 18012121 | AR14: =Inputs!$D$64-(A14-1) -> 64 | AS14: =IF(AR14<=0,0,IF(A14=1,Inputs!$B$64,AX13)) -> 29437425 | AT14: =AS14*Inputs!$B$9 -> 74625.303 | AU14: =(AS14-AT14)*Inputs!$C$64/12 -> 239796.2 | AV14: =IF(AR14<=0,0,IF(AR14=1,AS14-AT14,MIN((AS14-AT14)*(Inputs!$C$64/12)/(1-(1+Inputs!$C$64/12)^(-AR14))-AU14,AS14-AT14))) -> 351121.88 | AW14: =(AS14-AT14-AV14)*Inputs!$B$10 -> 253608.8 | AX14: =AS14-AT14-AV14-AW14 -> 28758069 | AY14: =Inputs!$D$65-(A14-1) -> 64 | AZ14: =IF(AY14<=0,0,IF(A14=1,Inputs!$B$65,BE13)) -> 30481904 | BA14: =AZ14*Inputs!$B$9 -> 77273.11 | BB14: =(AZ14-BA14)*Inputs!$C$65/12 -> 260973.09 | BC14: =IF(AY14<=0,0,IF(AY14=1,AZ14-BA14,MIN((AZ14-BA14)*(Inputs!$C$65/12)/(1-(1+Inputs!$C$65/12)^(-AY14))-BB14,AZ14-BA14))) -> 358458.66 | BD14: =(AZ14-BA14-BC14)*Inputs!$B$10 -> 262651.95 | BE14: =AZ14-BA14-BC14-BD14 -> 29783521 | BF14: =Inputs!$D$66-(A14-1) -> 76 | BG14: =IF(BF14<=0,0,IF(A14=1,Inputs!$B$66,BL13)) -> 30772537 | BH14: =BG14*Inputs!$B$9 -> 78009.877 | BI14: =(BG14-BH14)*Inputs!$C$66/12 -> 269856.05 | BJ14: =IF(BF14<=0,0,IF(BF14=1,BG14-BH14,MIN((BG14-BH14)*(Inputs!$C$66/12)/(1-(1+Inputs!$C$66/12)^(-BF14))-BI14,BG14-BH14))) -> 285570.98 | BK14: =(BG14-BH14-BJ14)*Inputs!$B$10 -> 265823.26 | BL14: =BG14-BH14-BJ14-BK14 -> 30143133 | BM14: =Inputs!$D$67-(A14-1) -> 76 | BN14: =IF(BM14<=0,0,IF(A14=1,Inputs!$B$67,BS13)) -> 40370683 | BO14: =BN14*Inputs!$B$9 -> 102341.64 | BP14: =(BN14-BO14)*Inputs!$C$67/12 -> 370804.31 | BQ14: =IF(BM14<=0,0,IF(BM14=1,BN14-BO14,MIN((BN14-BO14)*(Inputs!$C$67/12)/(1-(1+Inputs!$C$67/12)^(-BM14))-BP14,BN14-BO14))) -> 368234.24 | BR14: =(BN14-BO14-BQ14)*Inputs!$B$10 -> 348791.22 | BS14: =BN14-BO14-BQ14-BR14 -> 39551316 | BT14: =C14+J14+Q14+X14+AE14+AL14+AS14+AZ14+BG14+BN14 -> 3.2386411e+08 | BU14: =D14+K14+R14+Y14+AF14+AM14+AT14+BA14+BH14+BO14 -> 821011.27 | BV14: =E14+L14+S14+Z14+AG14+AN14+AU14+BB14+BI14+BP14 -> 2478347.4 | BW14: =F14+M14+T14+AA14+AH14+AO14+AV14+BC14+BJ14+BQ14 -> 5346431.4 | BX14: =G14+N14+U14+AB14+AI14+AP14+AW14+BD14+BK14+BR14 -> 2777180.7 | BY14: =H14+O14+V14+AC14+AJ14+AQ14+AX14+BE14+BL14+BS14 -> 3.1491949e+08 | BZ14: =IF(A14>Inputs!$B$7,(1-Inputs!$B$6)*INDEX($BU$6:$BU$125,A14-Inputs!$B$7),0) -> 578266.66 | CA14: =CA13+(1-Inputs!$B$6)*BU14-BZ14 -> 3166377.9 | CB14: =BY14+CA14 -> 3.1808587e+08 | CC14: =BV14+BW14+BX14+BZ14 -> 11180226 | CD14: =CD13+BU14-BZ14 -> 6463906.7
A15: =ROW()-5 -> 10 | B15: =Inputs!$D$58-(A15-1) -> 27 | C15: =IF(B15<=0,0,IF(A15=1,Inputs!$B$58,H14)) -> 27124527 | D15: =C15*Inputs!$B$9 -> 68761.996 | E15: =(C15-D15)*Inputs!$C$58/12 -> 164589.24 | F15: =IF(B15<=0,0,IF(B15=1,C15-D15,MIN((C15-D15)*(Inputs!$C$58/12)/(1-(1+Inputs!$C$58/12)^(-B15))-E15,C15-D15))) -> 925060.62 | G15: =(C15-D15-F15)*Inputs!$B$10 -> 228424.46 | H15: =C15-D15-F15-G15 -> 25902280 | I15: =Inputs!$D$59-(A15-1) -> 39 | J15: =IF(I15<=0,0,IF(A15=1,Inputs!$B$59,O14)) -> 56963811 | K15: =J15*Inputs!$B$9 -> 144406.03 | L15: =(J15-K15)*Inputs!$C$59/12 -> 369326.13 | M15: =IF(I15<=0,0,IF(I15=1,J15-K15,MIN((J15-K15)*(Inputs!$C$59/12)/(1-(1+Inputs!$C$59/12)^(-I15))-L15,J15-K15))) -> 1284743.1 | N15: =(J15-K15-M15)*Inputs!$B$10 -> 485462.41 | O15: =J15-K15-M15-N15 -> 55049200 | P15: =Inputs!$D$60-(A15-1) -> 39 | Q15: =IF(P15<=0,0,IF(A15=1,Inputs!$B$60,V14)) -> 16324373 | R15: =Q15*Inputs!$B$9 -> 41383.08 | S15: =(Q15-R15)*Inputs!$C$60/12 -> 112624.02 | T15: =IF(P15<=0,0,IF(P15=1,Q15-R15,MIN((Q15-R15)*(Inputs!$C$60/12)/(1-(1+Inputs!$C$60/12)^(-P15))-S15,Q15-R15))) -> 365162.75 | U15: =(Q15-R15-T15)*Inputs!$B$10 -> 139147.46 | V15: =Q15-R15-T15-U15 -> 15778680 | W15: =Inputs!$D$61-(A15-1) -> 51 | X15: =IF(W15<=0,0,IF(A15=1,Inputs!$B$61,AC14)) -> 53194395 | Y15: =X15*Inputs!$B$9 -> 134850.38 | Z15: =(X15-Y15)*Inputs!$C$61/12 -> 389103.32 | AA15: =IF(W15<=0,0,IF(W15=1,X15-Y15,MIN((X15-Y15)*(Inputs!$C$61/12)/(1-(1+Inputs!$C$61/12)^(-W15))-Z15,X15-Y15))) -> 861696.58 | AB15: =(X15-Y15-AA15)*Inputs!$B$10 -> 456293.28 | AC15: =X15-Y15-AA15-AB15 -> 51741554 | AD15: =Inputs!$D$62-(A15-1) -> 51 | AE15: =IF(AD15<=0,0,IF(A15=1,Inputs!$B$62,AJ14)) -> 15064222 | AF15: =AE15*Inputs!$B$9 -> 38188.536 | AG15: =(AE15-AF15)*Inputs!$C$62/12 -> 116451.76 | AH15: =IF(AD15<=0,0,IF(AD15=1,AE15-AF15,MIN((AE15-AF15)*(Inputs!$C$62/12)/(1-(1+Inputs!$C$62/12)^(-AD15))-AG15,AE15-AF15))) -> 241353.46 | AI15: =(AE15-AF15-AH15)*Inputs!$B$10 -> 129241.92 | AJ15: =AE15-AF15-AH15-AI15 -> 14655438 | AK15: =Inputs!$D$63-(A15-1) -> 51 | AL15: =IF(AK15<=0,0,IF(A15=1,Inputs!$B$63,AQ14)) -> 18012121 | AM15: =AL15*Inputs!$B$9 -> 45661.602 | AN15: =(AL15-AM15)*Inputs!$C$63/12 -> 142983.07 | AO15: =IF(AK15<=0,0,IF(AK15=1,AL15-AM15,MIN((AL15-AM15)*(Inputs!$C$63/12)/(1-(1+Inputs!$C$63/12)^(-AK15))-AN15,AL15-AM15))) -> 286995.81 | AP15: =(AL15-AM15-AO15)*Inputs!$B$10 -> 154546.99 | AQ15: =AL15-AM15-AO15-AP15 -> 17524916 | AR15: =Inputs!$D$64-(A15-1) -> 63 | AS15: =IF(AR15<=0,0,IF(A15=1,Inputs!$B$64,AX14)) -> 28758069 | AT15: =AS15*Inputs!$B$9 -> 72903.103 | AU15: =(AS15-AT15)*Inputs!$C$64/12 -> 234262.19 | AV15: =IF(AR15<=0,0,IF(AR15=1,AS15-AT15,MIN((AS15-AT15)*(Inputs!$C$64/12)/(1-(1+Inputs!$C$64/12)^(-AR15))-AU15,AS15-AT15))) -> 350005.4 | AW15: =(AS15-AT15-AV15)*Inputs!$B$10 -> 247694.95 | AX15: =AS15-AT15-AV15-AW15 -> 28087466 | AY15: =Inputs!$D$65-(A15-1) -> 63 | AZ15: =IF(AY15<=0,0,IF(A15=1,Inputs!$B$65,BE14)) -> 29783521 | BA15: =AZ15*Inputs!$B$9 -> 75502.673 | BB15: =(AZ15-BA15)*Inputs!$C$65/12 -> 254993.82 | BC15: =IF(AY15<=0,0,IF(AY15=1,AZ15-BA15,MIN((AZ15-BA15)*(Inputs!$C$65/12)/(1-(1+Inputs!$C$65/12)^(-AY15))-BB15,AZ15-BA15))) -> 357466.53 | BD15: =(AZ15-BA15-BC15)*Inputs!$B$10 -> 256571.1 | BE15: =AZ15-BA15-BC15-BD15 -> 29093980 | BF15: =Inputs!$D$66-(A15-1) -> 75 | BG15: =IF(BF15<=0,0,IF(A15=1,Inputs!$B$66,BL14)) -> 30143133 | BH15: =BG15*Inputs!$B$9 -> 76414.307 | BI15: =(BG15-BH15)*Inputs!$C$66/12 -> 264336.57 | BJ15: =IF(BF15<=0,0,IF(BF15=1,BG15-BH15,MIN((BG15-BH15)*(Inputs!$C$66/12)/(1-(1+Inputs!$C$66/12)^(-BF15))-BI15,BG15-BH15))) -> 284839.41 | BK15: =(BG15-BH15-BJ15)*Inputs!$B$10 -> 260341.6 | BL15: =BG15-BH15-BJ15-BK15 -> 29521537 | BM15: =Inputs!$D$67-(A15-1) -> 75 | BN15: =IF(BM15<=0,0,IF(A15=1,Inputs!$B$67,BS14)) -> 39551316 | BO15: =BN15*Inputs!$B$9 -> 100264.51 | BP15: =(BN15-BO15)*Inputs!$C$67/12 -> 363278.44 | BQ15: =IF(BM15<=0,0,IF(BM15=1,BN15-BO15,MIN((BN15-BO15)*(Inputs!$C$67/12)/(1-(1+Inputs!$C$67/12)^(-BM15))-BP15,BN15-BO15))) -> 367442.61 | BR15: =(BN15-BO15-BQ15)*Inputs!$B$10 -> 341653.71 | BS15: =BN15-BO15-BQ15-BR15 -> 38741955 | BT15: =C15+J15+Q15+X15+AE15+AL15+AS15+AZ15+BG15+BN15 -> 3.1491949e+08 | BU15: =D15+K15+R15+Y15+AF15+AM15+AT15+BA15+BH15+BO15 -> 798336.21 | BV15: =E15+L15+S15+Z15+AG15+AN15+AU15+BB15+BI15+BP15 -> 2411948.6 | BW15: =F15+M15+T15+AA15+AH15+AO15+AV15+BC15+BJ15+BQ15 -> 5324766.3 | BX15: =G15+N15+U15+AB15+AI15+AP15+AW15+BD15+BK15+BR15 -> 2699377.9 | BY15: =H15+O15+V15+AC15+AJ15+AQ15+AX15+BE15+BL15+BS15 -> 3.0609701e+08 | BZ15: =IF(A15>Inputs!$B$7,(1-Inputs!$B$6)*INDEX($BU$6:$BU$125,A15-Inputs!$B$7),0) -> 563498.6 | CA15: =CA14+(1-Inputs!$B$6)*BU15-BZ15 -> 3081881.1 | CB15: =BY15+CA15 -> 3.0917889e+08 | CC15: =BV15+BW15+BX15+BZ15 -> 10999591 | CD15: =CD14+BU15-BZ15 -> 6698744.3
A16: =ROW()-5 -> 11 | B16: =Inputs!$D$58-(A16-1) -> 26 | C16: =IF(B16<=0,0,IF(A16=1,Inputs!$B$58,H15)) -> 25902280 | D16: =C16*Inputs!$B$9 -> 65663.54 | E16: =(C16-D16)*Inputs!$C$58/12 -> 157172.75 | F16: =IF(B16<=0,0,IF(B16=1,C16-D16,MIN((C16-D16)*(Inputs!$C$58/12)/(1-(1+Inputs!$C$58/12)^(-B16))-E16,C16-D16))) -> 920213.65 | G16: =(C16-D16-F16)*Inputs!$B$10 -> 217809.5 | H16: =C16-D16-F16-G16 -> 24698594 | I16: =Inputs!$D$59-(A16-1) -> 38 | J16: =IF(I16<=0,0,IF(A16=1,Inputs!$B$59,O15)) -> 55049200 | K16: =J16*Inputs!$B$9 -> 139552.4 | L16: =(J16-K16)*Inputs!$C$59/12 -> 356912.71 | M16: =IF(I16<=0,0,IF(I16=1,J16-K16,MIN((J16-K16)*(Inputs!$C$59/12)/(1-(1+Inputs!$C$59/12)^(-I16))-L16,J16-K16))) -> 1278540.8 | N16: =(J16-K16-M16)*Inputs!$B$10 -> 468822.27 | O16: =J16-K16-M16-N16 -> 53162284 | P16: =Inputs!$D$60-(A16-1) -> 38 | Q16: =IF(P16<=0,0,IF(A16=1,Inputs!$B$60,V15)) -> 15778680 | R16: =Q16*Inputs!$B$9 -> 39999.721 | S16: =(Q16-R16)*Inputs!$C$60/12 -> 108859.21 | T16: =IF(P16<=0,0,IF(P16=1,Q16-R16,MIN((Q16-R16)*(Inputs!$C$60/12)/(1-(1+Inputs!$C$60/12)^(-P16))-S16,Q16-R16))) -> 363550.31 | U16: =(Q16-R16-T16)*Inputs!$B$10 -> 134403.41 | V16: =Q16-R16-T16-U16 -> 15240727 | W16: =Inputs!$D$61-(A16-1) -> 50 | X16: =IF(W16<=0,0,IF(A16=1,Inputs!$B$61,AC15)) -> 51741554 | Y16: =X16*Inputs!$B$9 -> 131167.36 | Z16: =(X16-Y16)*Inputs!$C$61/12 -> 378476.17 | AA16: =IF(W16<=0,0,IF(W16=1,X16-Y16,MIN((X16-Y16)*(Inputs!$C$61/12)/(1-(1+Inputs!$C$61/12)^(-W16))-Z16,X16-Y16))) -> 858246.61 | AB16: =(X16-Y16-AA16)*Inputs!$B$10 -> 443655.47 | AC16: =X16-Y16-AA16-AB16 -> 50308485 | AD16: =Inputs!$D$62-(A16-1) -> 50 | AE16: =IF(AD16<=0,0,IF(A16=1,Inputs!$B$62,AJ15)) -> 14655438 | AF16: =AE16*Inputs!$B$9 -> 37152.249 | AG16: =(AE16-AF16)*Inputs!$C$62/12 -> 113291.72 | AH16: =IF(AD16<=0,0,IF(AD16=1,AE16-AF16,MIN((AE16-AF16)*(Inputs!$C$62/12)/(1-(1+Inputs!$C$62/12)^(-AD16))-AG16,AE16-AF16))) -> 240486.58 | AI16: =(AE16-AF16-AH16)*Inputs!$B$10 -> 125685.13 | AJ16: =AE16-AF16-AH16-AI16 -> 14252115 | AK16: =Inputs!$D$63-(A16-1) -> 50 | AL16: =IF(AK16<=0,0,IF(A16=1,Inputs!$B$63,AQ15)) -> 17524916 | AM16: =AL16*Inputs!$B$9 -> 44426.515 | AN16: =(AL16-AM16)*Inputs!$C$63/12 -> 139115.57 | AO16: =IF(AK16<=0,0,IF(AK16=1,AL16-AM16,MIN((AL16-AM16)*(Inputs!$C$63/12)/(1-(1+Inputs!$C$63/12)^(-AK16))-AN16,AL16-AM16))) -> 286024.12 | AP16: =(AL16-AM16-AO16)*Inputs!$B$10 -> 150307.33 | AQ16: =AL16-AM16-AO16-AP16 -> 17044158 | AR16: =Inputs!$D$64-(A16-1) -> 62 | AS16: =IF(AR16<=0,0,IF(A16=1,Inputs!$B$64,AX15)) -> 28087466 | AT16: =AS16*Inputs!$B$9 -> 71203.09 | AU16: =(AS16-AT16)*Inputs!$C$64/12 -> 228799.48 | AV16: =IF(AR16<=0,0,IF(AR16=1,AS16-AT16,MIN((AS16-AT16)*(Inputs!$C$64/12)/(1-(1+Inputs!$C$64/12)^(-AR16))-AU16,AS16-AT16))) -> 348892.47 | AW16: =(AS16-AT16-AV16)*Inputs!$B$10 -> 241857.38 | AX16: =AS16-AT16-AV16-AW16 -> 27425513 | AY16: =Inputs!$D$65-(A16-1) -> 62 | AZ16: =IF(AY16<=0,0,IF(A16=1,Inputs!$B$65,BE15)) -> 29093980 | BA16: =AZ16*Inputs!$B$9 -> 73754.655 | BB16: =(AZ16-BA16)*Inputs!$C$65/12 -> 249090.27 | BC16: =IF(AY16<=0,0,IF(AY16=1,AZ16-BA16,MIN((AZ16-BA16)*(Inputs!$C$65/12)/(1-(1+Inputs!$C$65/12)^(-AY16))-BB16,AZ16-BA16))) -> 356477.14 | BD16: =(AZ16-BA16-BC16)*Inputs!$B$10 -> 250567.34 | BE16: =AZ16-BA16-BC16-BD16 -> 28413181 | BF16: =Inputs!$D$66-(A16-1) -> 74 | BG16: =IF(BF16<=0,0,IF(A16=1,Inputs!$B$66,BL15)) -> 29521537 | BH16: =BG16*Inputs!$B$9 -> 74838.533 | BI16: =(BG16-BH16)*Inputs!$C$66/12 -> 258885.56 | BJ16: =IF(BF16<=0,0,IF(BF16=1,BG16-BH16,MIN((BG16-BH16)*(Inputs!$C$66/12)/(1-(1+Inputs!$C$66/12)^(-BF16))-BI16,BG16-BH16))) -> 284109.72 | BK16: =(BG16-BH16-BJ16)*Inputs!$B$10 -> 254928.01 | BL16: =BG16-BH16-BJ16-BK16 -> 28907661 | BM16: =Inputs!$D$67-(A16-1) -> 74 | BN16: =IF(BM16<=0,0,IF(A16=1,Inputs!$B$67,BS15)) -> 38741955 | BO16: =BN16*Inputs!$B$9 -> 98212.74 | BP16: =(BN16-BO16)*Inputs!$C$67/12 -> 355844.46 | BQ16: =IF(BM16<=0,0,IF(BM16=1,BN16-BO16,MIN((BN16-BO16)*(Inputs!$C$67/12)/(1-(1+Inputs!$C$67/12)^(-BM16))-BP16,BN16-BO16))) -> 366652.68 | BR16: =(BN16-BO16-BQ16)*Inputs!$B$10 -> 334603.43 | BS16: =BN16-BO16-BQ16-BR16 -> 37942487 | BT16: =C16+J16+Q16+X16+AE16+AL16+AS16+AZ16+BG16+BN16 -> 3.0609701e+08 | BU16: =D16+K16+R16+Y16+AF16+AM16+AT16+BA16+BH16+BO16 -> 775970.8 | BV16: =E16+L16+S16+Z16+AG16+AN16+AU16+BB16+BI16+BP16 -> 2346447.9 | BW16: =F16+M16+T16+AA16+AH16+AO16+AV16+BC16+BJ16+BQ16 -> 5303194.1 | BX16: =G16+N16+U16+AB16+AI16+AP16+AW16+BD16+BK16+BR16 -> 2622639.3 | BY16: =H16+O16+V16+AC16+AJ16+AQ16+AX16+BE16+BL16+BS16 -> 2.973952e+08 | BZ16: =IF(A16>Inputs!$B$7,(1-Inputs!$B$6)*INDEX($BU$6:$BU$125,A16-Inputs!$B$7),0) -> 548930.26 | CA16: =CA15+(1-Inputs!$B$6)*BU16-BZ16 -> 2998533.3 | CB16: =BY16+CA16 -> 3.0039374e+08 | CC16: =BV16+BW16+BX16+BZ16 -> 10821212 | CD16: =CD15+BU16-BZ16 -> 6925784.9
A17: =ROW()-5 -> 12 | B17: =Inputs!$D$58-(A17-1) -> 25 | C17: =IF(B17<=0,0,IF(A17=1,Inputs!$B$58,H16)) -> 24698594 | D17: =C17*Inputs!$B$9 -> 62612.136 | E17: =(C17-D17)*Inputs!$C$58/12 -> 149868.89 | F17: =IF(B17<=0,0,IF(B17=1,C17-D17,MIN((C17-D17)*(Inputs!$C$58/12)/(1-(1+Inputs!$C$58/12)^(-B17))-E17,C17-D17))) -> 915392.07 | G17: =(C17-D17-F17)*Inputs!$B$10 -> 207356.16 | H17: =C17-D17-F17-G17 -> 23513233 | I17: =Inputs!$D$59-(A17-1) -> 37 | J17: =IF(I17<=0,0,IF(A17=1,Inputs!$B$59,O16)) -> 53162284 | K17: =J17*Inputs!$B$9 -> 134768.97 | L17: =(J17-K17)*Inputs!$C$59/12 -> 344678.85 | M17: =IF(I17<=0,0,IF(I17=1,J17-K17,MIN((J17-K17)*(Inputs!$C$59/12)/(1-(1+Inputs!$C$59/12)^(-I17))-L17,J17-K17))) -> 1272368.5 | N17: =(J17-K17-M17)*Inputs!$B$10 -> 452423.36 | O17: =J17-K17-M17-N17 -> 51302723 | P17: =Inputs!$D$60-(A17-1) -> 37 | Q17: =IF(P17<=0,0,IF(A17=1,Inputs!$B$60,V16)) -> 15240727 | R17: =Q17*Inputs!$B$9 -> 38635.983 | S17: =(Q17-R17)*Inputs!$C$60/12 -> 105147.79 | T17: =IF(P17<=0,0,IF(P17=1,Q17-R17,MIN((Q17-R17)*(Inputs!$C$60/12)/(1-(1+Inputs!$C$60/12)^(-P17))-S17,Q17-R17))) -> 361944.99 | U17: =(Q17-R17-T17)*Inputs!$B$10 -> 129726.78 | V17: =Q17-R17-T17-U17 -> 14710419 | W17: =Inputs!$D$61-(A17-1) -> 49 | X17: =IF(W17<=0,0,IF(A17=1,Inputs!$B$61,AC16)) -> 50308485 | Y17: =X17*Inputs!$B$9 -> 127534.45 | Z17: =(X17-Y17)*Inputs!$C$61/12 -> 367993.64 | AA17: =IF(W17<=0,0,IF(W17=1,X17-Y17,MIN((X17-Y17)*(Inputs!$C$61/12)/(1-(1+Inputs!$C$61/12)^(-W17))-Z17,X17-Y17))) -> 854810.45 | AB17: =(X17-Y17-AA17)*Inputs!$B$10 -> 431189.93 | AC17: =X17-Y17-AA17-AB17 -> 48894950 | AD17: =Inputs!$D$62-(A17-1) -> 49 | AE17: =IF(AD17<=0,0,IF(A17=1,Inputs!$B$62,AJ16)) -> 14252115 | AF17: =AE17*Inputs!$B$9 -> 36129.803 | AG17: =(AE17-AF17)*Inputs!$C$62/12 -> 110173.88 | AH17: =IF(AD17<=0,0,IF(AD17=1,AE17-AF17,MIN((AE17-AF17)*(Inputs!$C$62/12)/(1-(1+Inputs!$C$62/12)^(-AD17))-AG17,AE17-AF17))) -> 239622.82 | AI17: =(AE17-AF17-AH17)*Inputs!$B$10 -> 122175.92 | AJ17: =AE17-AF17-AH17-AI17 -> 13854186 | AK17: =Inputs!$D$63-(A17-1) -> 49 | AL17: =IF(AK17<=0,0,IF(A17=1,Inputs!$B$63,AQ16)) -> 17044158 | AM17: =AL17*Inputs!$B$9 -> 43207.77 | AN17: =(AL17-AM17)*Inputs!$C$63/12 -> 135299.23 | AO17: =IF(AK17<=0,0,IF(AK17=1,AL17-AM17,MIN((AL17-AM17)*(Inputs!$C$63/12)/(1-(1+Inputs!$C$63/12)^(-AK17))-AN17,AL17-AM17))) -> 285055.72 | AP17: =(AL17-AM17-AO17)*Inputs!$B$10 -> 146123.85 | AQ17: =AL17-AM17-AO17-AP17 -> 16569771 | AR17: =Inputs!$D$64-(A17-1) -> 61 | AS17: =IF(AR17<=0,0,IF(A17=1,Inputs!$B$64,AX16)) -> 27425513 | AT17: =AS17*Inputs!$B$9 -> 69525.008 | AU17: =(AS17-AT17)*Inputs!$C$64/12 -> 223407.23 | AV17: =IF(AR17<=0,0,IF(AR17=1,AS17-AT17,MIN((AS17-AT17)*(Inputs!$C$64/12)/(1-(1+Inputs!$C$64/12)^(-AR17))-AU17,AS17-AT17))) -> 347783.08 | AW17: =(AS17-AT17-AV17)*Inputs!$B$10 -> 236095.22 | AX17: =AS17-AT17-AV17-AW17 -> 26772109 | AY17: =Inputs!$D$65-(A17-1) -> 61 | AZ17: =IF(AY17<=0,0,IF(A17=1,Inputs!$B$65,BE16)) -> 28413181 | BA17: =AZ17*Inputs!$B$9 -> 72028.796 | BB17: =(AZ17-BA17)*Inputs!$C$65/12 -> 243261.56 | BC17: =IF(AY17<=0,0,IF(AY17=1,AZ17-BA17,MIN((AZ17-BA17)*(Inputs!$C$65/12)/(1-(1+Inputs!$C$65/12)^(-AY17))-BB17,AZ17-BA17))) -> 355490.5 | BD17: =(AZ17-BA17-BC17)*Inputs!$B$10 -> 244639.77 | BE17: =AZ17-BA17-BC17-BD17 -> 27741022 | BF17: =Inputs!$D$66-(A17-1) -> 73 | BG17: =IF(BF17<=0,0,IF(A17=1,Inputs!$B$66,BL16)) -> 28907661 | BH17: =BG17*Inputs!$B$9 -> 73282.326 | BI17: =(BG17-BH17)*Inputs!$C$66/12 -> 253502.25 | BJ17: =IF(BF17<=0,0,IF(BF17=1,BG17-BH17,MIN((BG17-BH17)*(Inputs!$C$66/12)/(1-(1+Inputs!$C$66/12)^(-BF17))-BI17,BG17-BH17))) -> 283381.89 | BK17: =(BG17-BH17-BJ17)*Inputs!$B$10 -> 249581.71 | BL17: =BG17-BH17-BJ17-BK17 -> 28301415 | BM17: =Inputs!$D$67-(A17-1) -> 73 | BN17: =IF(BM17<=0,0,IF(A17=1,Inputs!$B$67,BS16)) -> 37942487 | BO17: =BN17*Inputs!$B$9 -> 96186.048 | BP17: =(BN17-BO17)*Inputs!$C$67/12 -> 348501.35 | BQ17: =IF(BM17<=0,0,IF(BM17=1,BN17-BO17,MIN((BN17-BO17)*(Inputs!$C$67/12)/(1-(1+Inputs!$C$67/12)^(-BM17))-BP17,BN17-BO17))) -> 365864.45 | BR17: =(BN17-BO17-BQ17)*Inputs!$B$10 -> 327639.39 | BS17: =BN17-BO17-BQ17-BR17 -> 37152797 | BT17: =C17+J17+Q17+X17+AE17+AL17+AS17+AZ17+BG17+BN17 -> 2.973952e+08 | BU17: =D17+K17+R17+Y17+AF17+AM17+AT17+BA17+BH17+BO17 -> 753911.3 | BV17: =E17+L17+S17+Z17+AG17+AN17+AU17+BB17+BI17+BP17 -> 2281834.7 | BW17: =F17+M17+T17+AA17+AH17+AO17+AV17+BC17+BJ17+BQ17 -> 5281714.4 | BX17: =G17+N17+U17+AB17+AI17+AP17+AW17+BD17+BK17+BR17 -> 2546952.1 | BY17: =H17+O17+V17+AC17+AJ17+AQ17+AX17+BE17+BL17+BS17 -> 2.8881263e+08 | BZ17: =IF(A17>Inputs!$B$7,(1-Inputs!$B$6)*INDEX($BU$6:$BU$125,A17-Inputs!$B$7),0) -> 534559.26 | CA17: =CA16+(1-Inputs!$B$6)*BU17-BZ17 -> 2916320.8 | CB17: =BY17+CA17 -> 2.9172895e+08 | CC17: =BV17+BW17+BX17+BZ17 -> 10645060 | CD17: =CD16+BU17-BZ17 -> 7145136.9
